# Translations template for pypowervm.
# Copyright (C) 2015 ORGANIZATION
# This file is distributed under the same license as the pypowervm project.
# Automatically generated, 2015.
#
msgid ""
msgstr ""
"Project-Id-Version: pypowervm 0.0.3.dev181\n"
"Report-Msgid-Bugs-To: EMAIL@ADDRESS\n"
"POT-Creation-Date: 2015-09-03 10:32-0400\n"
"PO-Revision-Date: 2015-09-03 10:32-0400\n"
"Last-Translator: Automatically generated\n"
"Language-Team: none\n"
"MIME-Version: 1.0\n"
"Content-Type: text/plain; charset=utf-8\n"
"Content-Transfer-Encoding: 8bit\n"
"Generated-By: Babel 2.0\n"

#: pypowervm/exceptions.py:77
msgid "The virtual adapter configuration is invalid."
msgstr "Недопустимая конфигурация виртуального адаптера."

#: pypowervm/exceptions.py:81
#, python-format
msgid "%(attr)s is a required attribute for virtual machine '%(instance_name)s'."
msgstr "%(attr)s - обязательный атрибут для виртуальной машины %(instance_name)s."

#: pypowervm/exceptions.py:86
#, python-format
msgid ""
"'%(value)s' is not a valid value for %(attr)s for virtual machine "
"'%(instance_name)s'."
msgstr ""
"%(value)s не является допустимым значением атрибута %(attr)s виртуальной машины "
"'%(instance_name)s'."

#: pypowervm/exceptions.py:91
#, python-format
msgid ""
"The value for minimum %(attr)s (%(value)s) cannot be greater than the "
"desired %(attr)s (%(des_value)s) for virtual machine '%(instance_name)s'."
msgstr ""
"Минимальное значение %(attr)s (%(value)s) не может быть больше, чем "
"предпочтительное значение %(attr)s (%(des_value)s) для виртуальной машины '%(instance_name)s'."

#: pypowervm/exceptions.py:97
#, python-format
msgid ""
"The value for maximum %(attr)s (%(value)s) cannot be less than the "
"desired %(attr)s (%(des_value)s) for virtual machine '%(instance_name)s'."
msgstr ""
"Максимальное значение %(attr)s (%(value)s) не может быть меньше, чем "
"предпочтительное значение %(attr)s (%(des_value)s) для виртуальной машины '%(instance_name)s'."

#: pypowervm/exceptions.py:103
#, python-format
msgid ""
"If you specify a minimum or maximum value for %(attr)s, you must specify "
"both minimum and maximum %(attr)s for virtual machine "
"'%(instance_name)s'."
msgstr ""
"При указании минимального или максимального значения для %(attr)s необходимо указать "
"и минимальное, и максимальное значение %(attr)s для виртуальной машины "
"'%(instance_name)s'."

#: pypowervm/exceptions.py:109
#, python-format
msgid ""
"%(attr)s (%(value)d MB) is not a multiple of the region memory size "
"(%(lmb)d MB) for virtual machine '%(instance_name)s'. Specify a value "
"that is a multiple of the region memory size."
msgstr ""
"Значение %(attr)s (%(value)d МБ) не кратно размеру памяти области "
"(%(lmb)d МБ) для виртуальной машины '%(instance_name)s'. Укажите значение,"
"кратное размеру памяти области."

#: pypowervm/exceptions.py:116
#, python-format
msgid ""
"'%(availability_priority)s' is not a valid value for availability "
"priority for virtual machine '%(instance_name)s'. Specify a value between"
" 0 and 255."
msgstr ""
"%(availability_priority)s не является допустимым значением приоритета доступности "
"для виртуальной машины '%(instance_name)s'. Укажите значение от"
" 0 до 255."

#: pypowervm/exceptions.py:122
#, python-format
msgid ""
"'%(processor_compatibility)s' is not a valid option for processor "
"compatibility for virtual machine '%(instance_name)s'. Valid options "
"include the following: '%(valid_values)s'."
msgstr ""
"%(processor_compatibility)s не является допустимым режимом совместимости процессоров "
"для виртуальной машины '%(instance_name)s'. Допустимые"
"значения: %(valid_values)s'."

#: pypowervm/exceptions.py:129
#, python-format
msgid ""
"Changing '%(processor_compatibility)s' is not supported because for an "
"IBM i virtual machine '%(instance_name)s', its processor compatibility "
"mode can only be set as 'default' on Power6 host."
msgstr ""
"Изменение '%(processor_compatibility)s' не поддерживается, поскольку для"
"виртуальной машины IBM i '%(instance_name)s' режим совместимости "
"процессора на хосте Power6 может быть равен только значению 'default'. "

#: pypowervm/exceptions.py:137
#, python-format
msgid ""
"'%(value)s' is not valid for virtual machine '%(instance_name)s'. "
"%(option)s must either be true or false. "
msgstr ""
"Значение '%(value)s' недопустимо для виртуальной машины '%(instance_name)s'. "
"Значение %(option)s должно быть true или false. "

#: pypowervm/exceptions.py:143
#, python-format
msgid ""
"'%(ded_share_mode)s' is not a valid option for sharing mode for dedicated"
" processors for virtual machine '%(instance_name)s'. Valid options "
"include the following: '%(valid_values)s'."
msgstr ""
"%(ded_share_mode)s не является допустимым режимом совместного использования выделенных "
" процессоров для виртуальной машины '%(instance_name)s'. Допустимые "
"значения: %(valid_values)s'."

#: pypowervm/exceptions.py:150
#, python-format
msgid ""
"'%(option)s' is not a valid option for dedicated processor mode for "
"virtual machine '%(instance_name)s'."
msgstr ""
"%(option)s не является допустимым режимом выделенных процессоров для "
"виртуальной машины '%(instance_name)s'."

#: pypowervm/exceptions.py:155
#, python-format
msgid ""
"'%(option)s' is not a valid option for shared processor mode for virtual "
"machine '%(instance_name)s'."
msgstr ""
"%(option)s не является допустимым режимом общих процессоров для виртуальной "
"машины '%(instance_name)s'."

#: pypowervm/exceptions.py:160
#, python-format
msgid ""
"Sharing weight is not a valid option for capped sharing mode for virtual "
"machine '%(instance_name)s'."
msgstr ""
"Весовой коэффициент не является допустимым режимом совместного использования с ограничениями для виртуальной "
"машины '%(instance_name)s'."

#: pypowervm/exceptions.py:165
#, python-format
msgid ""
"'%(shared_weight)s' is not a valid value for shared processor weight for "
"virtual machine '%(instance_name)s'. Specify a value between 0 and 255."
msgstr ""
"'%(shared_weight)s' не является допустимым весом общих процессоров для "
"виртуальной машины '%(instance_name)s'. Укажите значение от 0 до 255."

#: pypowervm/exceptions.py:171
#, python-format
msgid ""
"If you specify a minimum and maximum value for processing units, you must"
" also specify a minimum and maximum value for virtual CPUs for virtual "
"machine '%(instance_name)s'."
msgstr ""
"При указании минимального и максимального количества логических процессоров необходимо"
" также указать минимальное и максимальное количество виртуальных процессоров для виртуальной "
"машины '%(instance_name)s'."

#: pypowervm/exceptions.py:177
#, python-format
msgid ""
"If you specify a minimum and maximum value for processing units, you must"
" also specify a value for desired processing units for virtual machine "
"'%(instance_name)s'."
msgstr ""
"При указании минимального и максимального количества логических процессоров необходимо"
" также указать предпочтительное число логических процессоров для виртуальной машины "
"'%(instance_name)s'."

#: pypowervm/exceptions.py:183
#, python-format
msgid ""
"There must be a minimum of %(proc_units_per_vcpu)s processing units per "
"virtual CPU. The requested %(level)s processing units were "
"'%(proc_units)s' and the requested %(level)s virtual CPUs were "
"'%(vcpus)d' for virtual machine '%(instance_name)s'."
msgstr ""
"Должно быть не менее %(proc_units_per_vcpu)s логических процессоров на "
"виртуальный процессор. Запрошено логических процессоров %(level)s:"
"'%(proc_units)s', запрошено виртуальных процессоров %(level)s: "
"'%(vcpus)d' для виртуальной машины '%(instance_name)s'."

#: pypowervm/exceptions.py:191
#, python-format
msgid ""
"The number of processing units cannot be a larger value than the number "
"of virtual CPUs. The requested %(level)s processing units were "
"'%(proc_units)s' and the requested %(level)s virtual CPUs were "
"'%(vcpus)d' for virtual machine '%(instance_name)s'."
msgstr ""
"Число логических процессоров не должно превышать количество "
"виртуальных процессоров. Запрошено логических процессоров %(level)s: "
"'%(proc_units)s', запрошено виртуальных процессоров %(level)s: "
"'%(vcpus)d' для виртуальной машины '%(instance_name)s'."

#: pypowervm/exceptions.py:199
#, python-format
msgid ""
"The desired processors (%(vcpus)d) cannot be above the maximum processors"
" allowed per partition (%(max_allowed)d) for virtual machine "
"'%(instance_name)s'."
msgstr ""
"Предпочтительное количество процессоров (%(vcpus)d) не должно превышать максимально допустимого "
" числа процессоров на раздел (%(max_allowed)d) для виртуальной машины "
"'%(instance_name)s'."

#: pypowervm/exceptions.py:205
#, python-format
msgid ""
"The maximum processors (%(vcpus)d) cannot be above the maximum system "
"capacity processor limit %(max_allowed)d) for virtual machine "
"'%(instance_name)s'."
msgstr ""
"Максимальное количество процессоров (%(vcpus)d) не должно превышать "
"ограничения на количество процессоров в системе (%(max_allowed)d) для виртуальной машины "
"'%(instance_name)s'."

#: pypowervm/exceptions.py:211
#, python-format
msgid ""
"Unable to resize virtual machine '%(instance_name)s'. Resizing an active "
"virtual machine requires RMC connectivity."
msgstr ""
"Не удалось изменить размер виртуальной машины '%(instance_name)s'. Для изменения размера "
"активной виртуальной машины требуется подключение к RMC. "

#: pypowervm/exceptions.py:217
#, python-format
msgid ""
"Unable to determine that the volume with id %(uuid)s has been discovered "
"or mapped on a Virtual I/O Server"
msgstr ""
"Не удалось определить, что том с ИД %(uuid)s был обнаружен "
"или связан с VIOS"

#: pypowervm/exceptions.py:222
msgid "Unable to locate the Virtual I/O Server for this operation"
msgstr "Не удалось найти VIOS для этой операции"

#: pypowervm/exceptions.py:226
#, python-format
msgid ""
"The storage type specified '%(storage_type)s' is not supported for this "
"operation"
msgstr ""
"Указанный тип памяти %(storage_type)s не поддерживается для этой "
"операции "

#: pypowervm/exceptions.py:231
#, python-format
msgid ""
"Desired %(attr)s requested (%(desired)s) is outside the currently "
"assigned minimum (%(min)s) and maximum (%(max)s) values for virtual "
"machine '%(instance_name)s'. Either specify a valid value for desired "
"%(attr)s or power off the virtual machine before resizing."
msgstr ""
"Запрошенный предпочтительный %(attr)s (%(desired)s) находится за пределами текущего "
"диапазона (от %(min)s до %(max)s) значений для виртуальной "
"машины '%(instance_name)s'. Укажите правильное значение для предпочтительного "
"%(attr)s или выключите виртуальную машину перед изменением размера. "

#: pypowervm/exceptions.py:239
#, python-format
msgid ""
"Changing %(attr)s is not supported while virtual machine "
"'%(instance_name)s' is running. The virtual machine must be powered off "
"first."
msgstr ""
"Изменение %(attr)s не поддерживается, если виртуальная машина "
"'%(instance_name)s' выполняется. Виртуальная машина должна быть "
"сначала выключена. "

#: pypowervm/exceptions.py:245
#, python-format
msgid ""
"Failed to update object properties for %(uuid)s because the object "
"information is out of date."
msgstr ""
"Не удалось обновить свойства объекта для %(uuid)s: "
"информация об объекте устарела. "

#: pypowervm/exceptions.py:250
#, python-format
msgid ""
"Unable to find a supported storage connection type in the list of storage"
" connectivity groups: %(scg_conn_types)s"
msgstr ""
"Не найден поддерживаемый тип подключения к памяти в списке "
" групп подключения к памяти: %(scg_conn_types)s"

#: pypowervm/exceptions.py:255
#, python-format
msgid ""
"Unable to create virtual adapter for attaching storage to virtual machine"
" %(instance_name)s. Reason: %(reason)s"
msgstr ""
"Не удалось создать виртуальный адаптер для подключения памяти к виртуальной машине"
" %(instance_name)s. Причина: %(reason)s"

#: pypowervm/exceptions.py:260
#, python-format
msgid ""
"Unable to perform this operation with the storage connectivity group "
"provided for virtual machine %(instance_name)s."
msgstr ""
"Не удалось выполнить эту операцию с группой подключения к памяти, "
"указанной для виртуальной машины %(instance_name)s."

#: pypowervm/exceptions.py:266
#, python-format
msgid ""
"Failed to update object properties for %(uuid)s because the object "
"information is incomplete."
msgstr ""
"Не удалось обновить свойства объекта для %(uuid)s: "
"неполная информация. "

#: pypowervm/exceptions.py:271
#, python-format
msgid ""
"Unable to configure storage for virtual machine '%(instance_name)s'. "
"Configuring storage for a virtual machine in Active state requires RMC "
"connectivity."
msgstr ""
"Не удалось настроить память для виртуальной машины %(instance_name)s. "
"Настройка памяти для виртуальной машины в активном состоянии требует "
"подключения к RMC. "

#: pypowervm/exceptions.py:277
#, python-format
msgid ""
"Invalid attribute name '%(key)s' was passed in as part of the flavor "
"extra specs for virtual machine '%(instance_name)s'."
msgstr ""
"Недопустимое имя атрибута %(key)s передано в дополнительных спецификациях "
"разновидности для виртуальной машины '%(instance_name)s'."

#: pypowervm/exceptions.py:283
msgid ""
"The operation cannot complete because the system is busy. Wait a few "
"minutes and then try the operation again."
msgstr ""
"Не удалось выполнить операцию: система занята. Повторите "
"операцию через несколько минут."

#: pypowervm/exceptions.py:288
#, python-format
msgid ""
"Unable to find volume group '%(volume_group_name)s' on Virtual I/O Server"
" '%(uuid)s'."
msgstr ""
"Не найдена группа томов %(volume_group_name)s в VIOS "
" '%(uuid)s'."

#: pypowervm/exceptions.py:293
#, python-format
msgid "Unable to retrieve host statistics for managed host %(host)s."
msgstr "Не удалось получить статистику для управляемого хоста %(host)s."

#: pypowervm/exceptions.py:298
#, python-format
msgid ""
"Unable to remove the virtual adapter from Virtual I/O Server %(uuid)s "
"because it is a required adapter."
msgstr ""
"Не удалось удалить виртуальный адаптер из VIOS %(uuid)s: "
"это обязательный адаптер. "

#: pypowervm/exceptions.py:303
#, python-format
msgid ""
"Unable to create virtual adapters on Virtual I/O Server '%(uuid)s'. Run "
"the Verify Environment tool. You can either click the Verify Environment "
"button on the GUI Home page or type the powervc-validate command on the "
"command line. Verify that a sufficient number of virtual resources are "
"configured for the Virtual I/O Server. Then, try the operation again."
msgstr ""
"Не удалось создать виртуальные адаптеры VIOS '%(uuid)s'. Запустите "
"инструмент проверки среды. Нажмите кнопку Проверить среду "
"на начальной странице GUI или введите команду powervc-validate в  "
"командной строке. Убедитесь, что настроено достаточное количество "
"виртуальных ресурсов для VIOS. Затем повторите операцию."

#: pypowervm/exceptions.py:313
#, python-format
msgid "The license for Virtual I/O Server %(vios_name)s has not been accepted."
msgstr "Лицензия на сервер VIOS %(vios_name)s не принята."

#: pypowervm/exceptions.py:318
#, python-format
msgid ""
"Virtual I/O Server %(vios_name)s is not running. The current state is: "
"%(vios_state)s"
msgstr ""
"Сервер VIOS %(vios_name)s не работает. Текущее состояние: "
"%(vios_state)s"

#: pypowervm/exceptions.py:323
#, python-format
msgid ""
"Virtual I/O Server %(vios_name)s does not have an active Resource "
"Monitoring Control state."
msgstr ""
"Для сервера VIOS %(vios_name)s не указано активное "
"состояние RMC. "

#: pypowervm/exceptions.py:328
#, python-format
msgid ""
"Virtual I/O Server %(vios_name)s is currently too busy to process update "
"operations."
msgstr ""
"Сервер VIOS %(vios_name)s слишком сильно загружен для выполнения "
"операций обновления. "

#: pypowervm/exceptions.py:333
#, python-format
msgid ""
"Virtual I/O Server %(vios_name)s does not have any fibre channel ports "
"listed in the storage connectivity group."
msgstr ""
"Для сервера VIOS %(vios_name)s не задан ни один порт Fibre Channel "
"в группе связи системы хранения. "

#: pypowervm/exceptions.py:339
#, python-format
msgid ""
"There are not enough Virtual I/O Servers with the necessary connectivity "
"within the storage connectivity group for virtual machine "
"'%(instance_name)s' volume configuration: (Requested: %(min_vios)s "
"Available: %(avail_vios)s). %(reasons)s"
msgstr ""
"В группе связи системы хранения недостаточно серверов VIOS с необходимым типом "
"подключения для конфигурации томов виртуальной машины "
"'%(instance_name)s' (Запрошено: %(min_vios)s "
"доступно: %(avail_vios)s). %(reasons)s"

#: pypowervm/exceptions.py:347
#, python-format
msgid ""
"Unable to configure storage adapters for virtual machine "
"%(instance_name)s on the required number of Virtual I/O Servers for the "
"volume. Minimum number of Virtual I/O Servers required per volume: "
"%(min_vios)s. %(reasons)s"
msgstr ""
"Не удалось настроить адаптеры памяти для виртуальной машины "
"%(instance_name)s на том количестве серверов VIOS, которое необходимо для "
"тома. Минимальное число серверов VIOS для каждого тома: "
"%(min_vios)s. %(reasons)s"

#: pypowervm/exceptions.py:355
#, python-format
msgid ""
"Unable to configure storage adapters for virtual machine "
"%(instance_name)s on available physical Fibre Channel ports that satisfy "
"the NPIV switch fabric requirement of the storage connectivity group. "
"%(reasons)s"
msgstr ""
"Не удалось настроить адаптеры памяти для виртуальной машины "
"%(instance_name)s на доступных физических портах Fibre Channel, которые соответствуют требованиям "
"к фабрике коммутатора NPIV, которые предъявляются группой связи системы хранения. "
"%(reasons)s"

#: pypowervm/exceptions.py:362
#, python-format
msgid ""
"Unable to derive the appropriate physical FC port for WWPN %(wwpn)s.  The"
" VIOS Extended Attribute Groups may have been insufficient.  The VIOS URI"
" for the query was %(vio_uri)s."
msgstr ""
"Не удалось получить подходящий физический порт FC для WWPN %(wwpn)s.  Групп "
" расширенных атрибутов VIOS может быть недостаточно. URI VIOS "
" для запроса: %(vio_uri)s."

#: pypowervm/exceptions.py:368
#, python-format
msgid ""
"The virtual machine %(name)s cannot use the specified port because it "
"would require MAC address %(mac)s to be set. The host does not support "
"custom MAC addresses."
msgstr ""
"Виртуальная машина %(name)s не может использовать указанный порт, так как "
"это потребует настройки MAC-адреса %(mac)s. Хост не поддерживает "
"пользовательские MAC-адреса. "

#: pypowervm/exceptions.py:374
msgid ""
"The operation failed because it is only allowed when the managed host is "
"in the Standby or Operating state."
msgstr ""
"Операция не выполнена, так как ее разрешено выполнять, только когда управляемый хост находится "
"в состоянии Работает или Ожидание. "

#: pypowervm/exceptions.py:379
msgid ""
"Error getting information from the Virtual I/O Server(s). This could be "
"because the it is down or too busy to process the request."
msgstr ""
"Ошибка получения информации от VIOS. Возможно, "
"сервер не работает или не смог обработать запрос из-за слишком большой нагрузки."

#: pypowervm/exceptions.py:385
#, python-format
msgid "Element not found: %(element_type)s %(element)s"
msgstr "Не найден элемент: %(element_type)s %(element)s"

#: pypowervm/exceptions.py:389
#, python-format
msgid "LPAR not found: %(lpar_name)s"
msgstr "Не найден LPAR: %(lpar_name)s"

#: pypowervm/exceptions.py:393
#, python-format
msgid "System not found: %(system_name)s"
msgstr "Не найдена система: %(system_name)s"

#: pypowervm/exceptions.py:397
#, python-format
msgid "The migration task failed. %(error)s"
msgstr "Сбой задачи миграции. %(error)s"

#: pypowervm/exceptions.py:401
#, python-format
msgid "Migration of %(lpar_name)s is already in progress."
msgstr "Миграция %(lpar_name)s уже выполняется."

#: pypowervm/exceptions.py:405
#, python-format
msgid "Unable to update progress for virtual machine '%(uuid)s'."
msgstr "Не удалось обновить ход выполнения для виртуальной машины %(uuid)s."

#: pypowervm/exceptions.py:409
#, python-format
msgid ""
"The media library is too small for the ISO image. The media library "
"requires %(medialib_mb_required)d MB of space but only "
"%(mediavg_mb_avail)d MB is available."
msgstr ""
"Библиотека носителей слишком мала для данного образа ISO. Библиотеке носителей требуется "
"%(medialib_mb_required)d МБ свободной памяти, но доступно только "
"%(mediavg_mb_avail)d МБ. "

#: pypowervm/exceptions.py:415
#, python-format
msgid ""
"Virtual machine '%(instance_name)s' is running during capture. Virtual "
"machines must be stopped before they can be captured."
msgstr ""
"Виртуальная машина %(instance_name)s работала в момент создания моментальной копии. Виртуальные "
"машины должны быть остановлены перед созданием моментальной копии. "

#: pypowervm/exceptions.py:421
#, python-format
msgid "Unable to find virtual machine '%(instance_name)s'."
msgstr "Не найдена виртуальная машина %(instance_name)s."

#: pypowervm/exceptions.py:425
msgid "Insufficient resources"
msgstr "Недостаточно ресурсов"

#: pypowervm/exceptions.py:429
#, python-format
msgid ""
"The requested memory (%(mem_requested)d MB) is below the minimum required"
" value (%(mem_min)d MB)"
msgstr ""
"Запрошенная память (%(mem_requested)d МБ) меньше минимального "
" значения (%(mem_min)d МБ)"

#: pypowervm/exceptions.py:434
#, python-format
msgid ""
"The requested disk (%(new_disk_size)d GB) is lesser than the existing "
"disk (%(disk_size)d GB)"
msgstr ""
"Запрошенный диск (%(new_disk_size)d ГБ) меньше существующего "
"(%(disk_size)d ГБ)"

#: pypowervm/exceptions.py:439
#, python-format
msgid ""
"The requested CPUs (%(cpus_requested)d) are below the minimum required "
"value (%(cpus_min)d) "
msgstr ""
"Запрошенное количество процессоров (%(cpus_requested)d) меньше минимального "
"(%(cpus_min)d) "

#: pypowervm/exceptions.py:444
#, python-format
msgid ""
"The requested processing units (%(units_requested)d) are below the "
"minimum required value (%(units_min)d) "
msgstr ""
"Запрошенное количество логических процессоров (%(units_requested)d) меньше "
"минимального (%(units_min)d) "

#: pypowervm/exceptions.py:449
#, python-format
msgid ""
"Insufficient free memory: (%(mem_requested)d MB requested, %(mem_avail)d "
"MB free)"
msgstr ""
"Недостаточно свободной памяти: запрошено %(mem_requested)d МБ, свободно %(mem_avail)d  "
"МБ "

#: pypowervm/exceptions.py:454
#, python-format
msgid ""
"Insufficient CPUs available on host for virtual machine "
"'%(instance_name)s' (%(cpus_requested)d requested and %(cpus_avail)d "
"available)"
msgstr ""
"На хосте недостаточно процессоров для виртуальной машины "
"'%(instance_name)s' (запрошено %(cpus_requested)d, "
"доступно %(cpus_avail)d)"

#: pypowervm/exceptions.py:460
#, python-format
msgid ""
"Insufficient available processing units: (%(units_requested)d requested, "
"%(units_avail)d available)"
msgstr ""
"Недостаточное количество доступных логических процессоров: запрошено %(units_requested)d, "
"доступно %(units_avail)d"

#: pypowervm/exceptions.py:466
#, python-format
msgid "The '%(operation_name)s' operation failed. %(error)s"
msgstr "Сбой операции %(operation_name)s. %(error)s"

#: pypowervm/exceptions.py:470
#, python-format
msgid ""
"The '%(operation_name)s' operation failed. Failed to complete the task in"
" %(seconds)d seconds."
msgstr ""
"Сбой операции %(operation_name)s. Не удалось выполнить задачу в течение "
" %(seconds)d сек."

#: pypowervm/exceptions.py:475
#, python-format
msgid "Virtual machine '%(instance_name)s' cleanup failed. Reason: %(reason)s"
msgstr "Сбой очистки виртуальной машины %(instance_name)s. Причина: %(reason)s"

#: pypowervm/exceptions.py:480
#, python-format
msgid "Failed to delete virtual machine. %(reason)s"
msgstr "Не удалось удалить виртуальную машину. %(reason)s"

#: pypowervm/exceptions.py:484
#, python-format
msgid ""
"The boot device name attribute is not defined for virtual machine "
"%(instance_name)s with ID %(instance_uuid)s."
msgstr ""
"Атрибут имени загрузочного устройства не определен для виртуальной машины  "
"%(instance_name)s с ИД %(instance_uuid)s."

#: pypowervm/exceptions.py:489
#, python-format
msgid ""
"Unable to change disk size for virtual machine %(instance_name)s because "
"disk size change is not supported for IBM i."
msgstr ""
"Невозможно изменить размер диска для виртуальной машины %(instance_name)s, "
"поскольку такое изменение не поддерживается для IBM i. "

#: pypowervm/exceptions.py:495
#, python-format
msgid ""
"Unable to save the captured image meta data for virtual machine "
"%(instance_name)s because the image object is invalid."
msgstr ""
"Не удалось сохранить собранные метаданные образа для виртуальной машины "
"%(instance_name)s: недопустимый объект образа. "

#: pypowervm/exceptions.py:501
#, python-format
msgid ""
"Boot volume %(volume)s is invalid for virtual machine %(instance_name)s "
"with ID %(instance_uuid)s."
msgstr ""
"Загрузочный том %(volume)s недопустим для виртуальной машины %(instance_name)s"
"с ИД %(instance_uuid)s."

#: pypowervm/exceptions.py:506
#, python-format
msgid ""
"Clone for boot volume %(image_volume)s failed for virtual machine "
"%(instance_name)s with ID %(instance_uuid)s."
msgstr ""
"Не удалось создать копию загрузочного тома %(image_volume)s для виртуальной машины "
"%(instance_name)s с ИД %(instance_uuid)s."

#: pypowervm/exceptions.py:511
msgid ""
"An error occurred while working with objects returned from the PowerVM "
"API."
msgstr ""
"Возникла ошибка во время работы с объектами, возвращенными функцией "
"API PowerVM. "

#: pypowervm/exceptions.py:516
#, python-format
msgid ""
"Virtual machine '%(instance_name)s' does not have an operating system "
"identified.  The process for bringing the virtual machine under "
"management by PowerVC must be completed."
msgstr ""
"В виртуальной машине '%(instance_name)s' не идентифицирована операционная "
"система. Процесс добавления виртуальной машины в управление "
"PowerVC должен быть завершен. "

#: pypowervm/exceptions.py:523
#, python-format
msgid ""
"The operating system %(os_distro)s for virtual machine "
"'%(instance_name)s' is not supported. Supported operating systems include"
" the following: %(options)s"
msgstr ""
"Операционная система %(os_distro)s для виртуальной машины "
"'%(instance_name)s' не поддерживается. Поддерживаемые операционные "
" системы: %(options)s"

#: pypowervm/exceptions.py:529
#, python-format
msgid ""
"Unable to capture virtual machine '%(instance_name)s' because IBM i does "
"not support multi-disks capture."
msgstr ""
"Не удалось скопировать виртуальную машину '%(instance_name)s', так как IBM i "
"не поддерживает копирование нескольких дисков. "

#: pypowervm/exceptions.py:534
#, python-format
msgid "An error occurred when extending volume %(volume_id)s"
msgstr "Ошибка расширения тома %(volume_id)s"

#: pypowervm/exceptions.py:538
#, python-format
msgid ""
"Unable to deploy virtual machine '%(instance_name)s' because the host "
"does not support the operating system installed on this image"
msgstr ""
"Не удалось развернуть виртуальную машину '%(instance_name)s', поскольку хост"
"не поддерживает операционную систему, установленную в этом образе"

#: pypowervm/exceptions.py:544
#, python-format
msgid ""
"Unable to deploy virtual machine '%(instance_name)s' because the host "
"does not support the operating systemversion installed on this image"
msgstr ""
"Не удалось развернуть виртуальную машину '%(instance_name)s', поскольку хост "
"не поддерживает ту версию операционной системы, которая установлена в этом образе"

#: pypowervm/exceptions.py:550
#, python-format
msgid "Failed to discover the volume error code %(status)s"
msgstr "Не удалось обнаружить том, код ошибки: %(status)s"

#: pypowervm/exceptions.py:554
#, python-format
msgid ""
"LUA Discovery Completed with few ITL Error:Device %(dev)s Discovered, "
"Status: %(status)sReason: %(msg)s"
msgstr ""
"При поиске LUA найдено несколько ошибок ITL: устройство %(dev)s найдено, "
"состояние: %(status)s, причина: %(msg)s"

#: pypowervm/exceptions.py:560
#, python-format
msgid "Failed to power off Virtual Machine %(lpar_nm)s: %(reason)s"
msgstr "Не удалось выключить виртуальную машину %(lpar_nm)s: %(reason)s"

#: pypowervm/exceptions.py:564
#, python-format
msgid "Failed to power on Virtual Machine %(lpar_nm)s: %(reason)s"
msgstr "Не удалось включить виртуальную машину %(lpar_nm)s: %(reason)s"

#: pypowervm/exceptions.py:568
#, python-format
msgid ""
"Unable to remove VLAN %(vlan_id)d as it is the Primary VLAN Identifier on"
" a different Network Bridge."
msgstr ""
"Не удалось удалить VLAN %(vlan_id)d, поскольку это идентификатор основной VLAN "
" в другом сетевом мосте. "

#: pypowervm/exceptions.py:573
#, python-format
msgid ""
"A Logical Unit with name %(lu_name)s already exists on Shared Storage "
"Pool %(ssp_name)s."
msgstr ""
"Логический накопитель с именем %(lu_name)s уже существует в общем пуле "
"памяти %(ssp_name)s."

#: pypowervm/exceptions.py:578
msgid ""
"Unable to find a physical port to map a virtual Fibre Channel port to.  "
"This is due to either a Virtual I/O Server being unavailable, or improper"
" port specification for the physical Fibre Channel ports."
msgstr ""
"Не удалось найти физический порт для связывания виртуального порта Fibre Channel. "
"Возможные причины: нет доступа к VIOS или неправильная "
" спецификация физических портов Fibre Channel. "

#: pypowervm/exceptions.py:585
msgid ""
"Unable to start the console to the Virtual Machine.  The pypowervm API is"
" running in a non-local mode.  The console can only be deployed when "
"pypowervm is co-located with the PowerVM API."
msgstr ""
"Не удалось запустить консоль в виртуальной машине. API pypowervm "
" работает в нелокальном режиме. Консоль можно развернуть только в том случае, если "
"pypowervm работает вместе с API PowerVM."

#: pypowervm/exceptions.py:592
#, python-format
msgid "WrapperTask %(name)s has no subtasks!"
msgstr "WrapperTask %(name)s не имеет подзадач!"

#: pypowervm/exceptions.py:596
msgid "FeedTask can't have an empty feed."
msgstr "FeedTask не может содержать пустую ленту. "

#: pypowervm/exceptions.py:600
#, python-format
msgid "Transaction %(name)s has no subtasks!"
msgstr "Транзакция %(name)s не имеет подзадач!"

#: pypowervm/exceptions.py:604
#, python-format
msgid "OS unable to read file %(access_file)s."
msgstr "ОС не удалось прочитать файл %(access_file)s."

#: pypowervm/exceptions.py:608
#, python-format
msgid "OS able to read file %(access_file)s, but encountered an access error."
msgstr "При чтении файла %(access_file)s операционной системой произошла ошибка доступа. "

#: pypowervm/util.py:125
#, python-format
msgid ""
"Proposed extended attribute group '%(arg_xag)s' doesn't match existing "
"extended attribute group '%(path_xag)s'"
msgstr ""
"Предложенная группа расширенных атрибутов '%(arg_xag)s' не совпадает с существующей "
"группой расширенных атрибутов '%(path_xag)s'"

#: pypowervm/util.py:394
#, python-format
msgid "Prefix and suffix together may not be more than %d characters."
msgstr "Общая длина префикса и суффикса не может превышать %d символов. "

#: pypowervm/util.py:399
msgid "Total length must be at least 1 character."
msgstr "Общая длина должна быть не меньше 1 символа. "

#: pypowervm/util.py:422
msgid "The name parameter must be at least one character long."
msgstr "Длина параметра имени должна быть не меньше одного символа. "

#: pypowervm/util.py:425
#, python-format
msgid "The name parameter must not exceed %d characters when trunk_ok is False."
msgstr "Длина параметра имени не должна превышать %d символов, если для параметра trunk_ok указано значение False."

#: pypowervm/helpers/log_helper.py:81
#, python-format
msgid "REQUEST: %s"
msgstr "ЗАПРОС: %s"

#: pypowervm/helpers/log_helper.py:101
#, python-format
msgid "RESPONSE: %s"
msgstr "ОТВЕТ: %s"

#: pypowervm/tasks/cna.py:77
#, python-format
msgid "Unable to find the Virtual Switch %s on the system."
msgstr "Не удалось найти виртуальный коммутатор %s в системе. "

#: pypowervm/tasks/hdisk.py:165
#, python-format
msgid ""
"hdisk discovery failed; will scrub stale storage for LPAR IDs %s and "
"retry."
msgstr ""
"Ошибка поиска жестких дисков; будет очищена старая память для ИД LPAR %s и "
"выполнена повторная попытка."

#: pypowervm/tasks/hdisk.py:308
#, python-format
msgid "LUA Discovery Successful Device Found: %s"
msgstr "При выполнении поиска LUA успешно найдено устройство %s"

#: pypowervm/tasks/hdisk.py:312
#, python-format
msgid "ITL Error encountered: %s"
msgstr "Ошибка ITL: %s"

#: pypowervm/tasks/hdisk.py:314
#, python-format
msgid "%s Device is currently in use"
msgstr "%s Устройство занято"

#: pypowervm/tasks/hdisk.py:316
#, python-format
msgid "%s Device discovered with unknown uuid"
msgstr "%s Обнаружено устройство с неизвестным uuid"

#: pypowervm/tasks/hdisk.py:318
#, python-format
msgid "Failed to Discover the Device : %s"
msgstr "Не удалось найти устройство: %s"

#: pypowervm/tasks/hdisk.py:388
#, python-format
msgid "CLIRunner Error: %s"
msgstr "Ошибка CLIRunner: %s"

#: pypowervm/tasks/memory.py:101
#, python-format
msgid ""
"Error obtaining host memory overhead for host with UUID '%(host)s' "
"%(error)s."
msgstr ""
"Ошибка получения накладных расходов памяти хоста с UUID '%(host)s' "
"%(error)s."

#: pypowervm/tasks/power.py:153 pypowervm/tasks/power.py:162
#, python-format
msgid "Error: %s"
msgstr "Ошибка: %s"

#: pypowervm/tasks/power.py:194
#, python-format
msgid ""
"Error invalidating adapter cache for LPAR  %(lpar_name) with UUID "
"%(lpar_uuid)s: %(exc)s"
msgstr ""
"Ошибка при аннулировании кэша адаптера для LPAR  %(lpar_name) с UUID "
"%(lpar_uuid)s: %(exc)s"

#: pypowervm/tasks/scsi_mapper.py:38
msgid "Retrying modification of SCSI Mapping."
msgstr "Повторная попытка изменения связей SCSI. "

#: pypowervm/tasks/scsi_mapper.py:88
#, python-format
msgid ""
"Found existing mapping of %(stg_type)s storage element %(stg_name)s from "
"Virtual I/O Server %(vios_name)s to client LPAR %(lpar_uuid)s."
msgstr ""
"Обнаружена существующая привязка элемента хранения данных %(stg_type)s с именем %(stg_name)s из "
"VIOS %(vios_name)s с клиентским LPAR %(lpar_uuid)s."

#: pypowervm/tasks/scsi_mapper.py:106
#, python-format
msgid ""
"Creating mapping of %(stg_type)s storage element %(stg_name)s from "
"Virtual I/O Server %(vios_name)s to client LPAR %(lpar_uuid)s."
msgstr ""
"Создание привязки элемента хранения данных %(stg_type)s с именем %(stg_name)s из "
"VIOS %(vios_name)s с клиентским LPAR %(lpar_uuid)s."

#: pypowervm/tasks/scsi_mapper.py:367
msgid "Must not specify both match_func and stg_elem."
msgstr "Одновременно нельзя указывать match_func и stg_elem."

#: pypowervm/tasks/storage.py:288
#, python-format
msgid "Unable to cleanup after file upload. File uuid: %s"
msgstr "Невозможно выполнить очистку после передачи файла. UUID файла: %s"

#: pypowervm/tasks/storage.py:425
msgid "Unable to locate new vDisk on file upload."
msgstr "Не удалось найти новый vDisk при передаче файла. "

#: pypowervm/tasks/storage.py:475
#, python-format
msgid "Deleting virtual disk %(vdisk)s from volume group %(vg)s"
msgstr "Удаление виртуального диска %(vdisk)s из группы томов %(vg)s"

#: pypowervm/tasks/storage.py:499
#, python-format
msgid "Deleting virtual optical device %(vopt)s from volume group %(vg)s"
msgstr "Удаление виртуального оптического накопителя %(vopt)s из группы томов %(vg)s"

#: pypowervm/tasks/storage.py:554
#, python-format
msgid "Removing LU %(lu_name)s from SSP %(ssp_name)s"
msgstr "Удаление LU %(lu_name)s из SSP %(ssp_name)s"

#: pypowervm/tasks/storage.py:575
#, python-format
msgid ""
"Removing Image LU %(lu_name)s from SSP %(ssp_name)s because it is no "
"longer in use."
msgstr ""
"Удаление LU образа %(lu_name)s из SSP %(ssp_name)s, поскольку он "
"больше не используется. "

#: pypowervm/tasks/storage.py:611
#, python-format
msgid ""
"Removing %(num_maps)d VSCSI mappings associated with LPAR ID %(lpar_id)d "
"from VIOS %(vios_name)s."
msgstr ""
"Удаление связей VSCSI (%(num_maps)d), связанных с ИД LPAR %(lpar_id)d "
"из VIOS %(vios_name)s."

#: pypowervm/tasks/storage.py:626
#, python-format
msgid ""
"Removing %(num_maps)d VFC mappings associated with LPAR ID %(lpar_id)d "
"from VIOS %(vios_name)s."
msgstr ""
"Удаление связей VFC (%(num_maps)d), связанных с ИД LPAR %(lpar_id)d "
"из VIOS %(vios_name)s."

#: pypowervm/tasks/storage.py:688
#, python-format
msgid "Unexpected storage element type %s."
msgstr "Непредвиденный тип элемента хранения данных %s."

#: pypowervm/tasks/storage.py:705
#, python-format
msgid ""
"Scrubbing the following %(vdcount)d Virtual Disks from VIOS %(vios)s: "
"%(vdlist)s"
msgstr ""
"Удаление следующих %(vdcount)d виртуальных дисков из VIOS %(vios)s: "
"%(vdlist)s"

#: pypowervm/tasks/storage.py:713
#, python-format
msgid ""
"Scrubbing the following %(vocount)d Virtual Opticals from VIOS %(vios)s: "
"%(volist)s"
msgstr ""
"Удаление следующих %(vocount)d виртуальных оптических накопителей из VIOS %(vios)s: "
"%(volist)s"

#: pypowervm/tasks/vfc_mapper.py:338
#, python-format
msgid "Detected a stale mapping for LPAR with UUID %s."
msgstr "Обнаружена устаревшая связь для LPAR с UUID %s."

#: pypowervm/tasks/vfc_mapper.py:635
#, python-format
msgid ""
"Unable to find appropriate VIOS.  The payload provided was likely "
"insufficient.  The payload data is:\n"
" %s)"
msgstr ""
"Не удалось найти подходящий VIOS.  Недостаточно"
"данных. Данные полезной нагрузки: \n"
" %s)"

#: pypowervm/tasks/vterm.py:63
msgid "Unable to close vterm."
msgstr "Не удалось закрыть vterm."

#: pypowervm/tasks/vterm.py:118
#, python-format
msgid ""
"Unable to run process.  Error is %(error)s\n"
"Command being run: %(cmd)s"
msgstr ""
"Не удалось запустить процесс. Ошибка: %(error)s\n"
"Выполняется команда: %(cmd)s"

#: pypowervm/tests/test_i18n.py:33
msgid "This is a test"
msgstr "Это тест"

#: pypowervm/tests/test_i18n.py:36
msgid "This is a message for which a translation doesn't exist"
msgstr "Это сообщение, для которого не существует перевод"

#: pypowervm/utils/retry.py:147
#, python-format
msgid ""
"Attempt %(retry)d of total %(total)d  for URI %(uri)s.  Error was a known"
" retry response code: %(resp_code)s"
msgstr ""
"Выполнено %(retry)d из %(total)d попыток для URI %(uri)s.  Получен "
" известный код ответа повторной попытки: %(resp_code)s"

#: pypowervm/utils/retry.py:154
#, python-format
msgid ""
"Attempt %(retry)d of %(total)d failed.  Will retry. The exception was:\n"
" %(except)s."
msgstr ""
"Попытка %(retry)d из %(total)d не выполнена. Операция будет выполнена повторно. Исключительная ситуация: \n"
" %(except)s."

#: pypowervm/utils/transaction.py:302
msgid "Must supply either EntryWrapper or EntryWrapperGetter"
msgstr "Необходимо указать EntryWrapper или EntryWrapperGetter"

#: pypowervm/utils/transaction.py:328
msgid "Must supply a valid Subtask."
msgstr "Необходимо указать допустимую подзадачу. "

#: pypowervm/utils/transaction.py:332
#, python-format
msgid "Duplicate 'provides' name %s."
msgstr "Повторяющееся имя 'provides' %s."

#: pypowervm/utils/transaction.py:406
#, python-format
msgid "WrapperTask %s has no Subtasks; no-op execution."
msgstr "WrapperTask %s не имеет подзадач; выполнение пустой операции. "

#: pypowervm/utils/transaction.py:531
msgid "Must supply either a list of EntryWrappers or a FeedGetter."
msgstr "Необходимо указать список EntryWrappers или FeedGetter."

#: pypowervm/utils/transaction.py:709
#, python-format
msgid "FeedTask %s has no Subtasks; no-op execution."
msgstr "FeedTask %s не имеет подзадач; выполнение пустой операции."

#: pypowervm/utils/validation.py:112
#, python-format
msgid ""
"Insufficient available %(res_name)s on host for virtual machine "
"'%(instance_name)s' (%(requested)s requested, %(avail)s available)"
msgstr ""
"Недостаточно %(res_name)s на хосте для виртуальной машины "
"'%(instance_name)s' (запрошено %(requested)s, доступно %(avail)s)"

#: pypowervm/utils/validation.py:131
msgid "CPUs"
msgstr "Процессоры"

#: pypowervm/utils/validation.py:135
msgid "processing units"
msgstr "логические процессоры"

#: pypowervm/wrappers/base_partition.py:448
#, python-format
msgid "Invalid KeylockPos '%s'."
msgstr "Недопустимый KeylockPos '%s'."

#: pypowervm/wrappers/entry_wrapper.py:258
#, python-format
msgid "Cannot convert %(property_name)s='%(value)s' in object %(pvmobject)s"
msgstr "Не удалось преобразовать %(property_name)s='%(value)s' в объект %(pvmobject)s"

#: pypowervm/wrappers/entry_wrapper.py:337
#, python-format
msgid "The expected parameter of %(param)s was not found in %(identifier)s"
msgstr "Не найден ожидаемый параметр %(param)s в %(identifier)s"

#: pypowervm/wrappers/entry_wrapper.py:386
msgid ""
"Refusing set href over multiple links.\n"
"Path: %{path}s\n"
"Number of links found: %{nlinks}d"
msgstr ""
"Нельзя указать href для нескольких ссылок. \n"
"Путь: %{path}s\n"
"Число найденных ссылок: %{nlinks}d"

#: pypowervm/wrappers/entry_wrapper.py:430
msgid "Refusing to construct and wrap an Element without a tag."
msgstr "Нельзя создать и добавить в оболочку без тега. "

#: pypowervm/wrappers/entry_wrapper.py:554
msgid "Response is missing 'entry' property."
msgstr "В ответе отсутствует свойство 'entry'. "

#: pypowervm/wrappers/entry_wrapper.py:568
#, python-format
msgid "Must supply a Response or Entry to wrap.  Got %s"
msgstr "Необходимо указать ответ или сущность для размещения.  Получено %s"

#: pypowervm/wrappers/entry_wrapper.py:640
msgid "Parent UUID specified without parent type."
msgstr "Родительский UUID указан без родительского типа. "

#: pypowervm/wrappers/entry_wrapper.py:643
msgid "The search() method requires exactly one key=value argument."
msgstr "Для метода search() требуется один аргумент ключ=значение. "

#: pypowervm/wrappers/entry_wrapper.py:671
#, python-format
msgid "Wrapper class %(class)s does not support search key '%(key)s'."
msgstr "Класс оболочки %(class)s не поддерживает ключ поиска '%(key)s'."

#: pypowervm/wrappers/entry_wrapper.py:747
msgid "Must specify both parent type and UUID, or neither."
msgstr "Необходимо указать родительский тип и UUID либо ни одно из этих значений. "

#: pypowervm/wrappers/entry_wrapper.py:824
msgid "Cannot set uuid."
msgstr "Не удалось указать uuid."

#: pypowervm/wrappers/entry_wrapper.py:1014
msgid "No such child element."
msgstr "Нет такого дочернего элемента. "

#: pypowervm/wrappers/entry_wrapper.py:1075
msgid "Cannot set UUID on Wrapper with no Metadata"
msgstr "Невозможно указать UUID для оболочки без метаданных"

#: pypowervm/wrappers/entry_wrapper.py:1080
#, python-format
msgid "uuid value not valid: %s"
msgstr "Недопустимое значение uuid: %s"

#: pypowervm/wrappers/entry_wrapper.py:1131
msgid "Must specify both parent class and parent UUID, or neither"
msgstr "Необходимо указать родительский класс и родительский UUID либо ни одно из этих значений"

#: pypowervm/wrappers/job.py:135
#, python-format
msgid "%s"
msgstr "%s"

#: pypowervm/wrappers/job.py:282
#, python-format
msgid "Job %(job_id)s failed to cancel after %(timeout)s seconds."
msgstr "Не удалось отменить задание %(job_id)s через %(timeout)s с."

#: pypowervm/wrappers/job.py:303
#, python-format
msgid "Job %s not deleted. Job is in running state."
msgstr "Задание %s не удалено. Задание находится в состоянии выполнения."

#: pypowervm/wrappers/logical_partition.py:125
#: pypowervm/wrappers/logical_partition.py:194
msgid "LPAR does not have an active RMC connection."
msgstr "В LPAR нет активных соединений RMC. "

#: pypowervm/wrappers/logical_partition.py:127
#, python-format
msgid "LPAR does not have an active DLPAR capability for %s."
msgstr "В LPAR отсутствует активная функция DLPAR для %s."

#: pypowervm/wrappers/logical_partition.py:139
msgid "I/O"
msgstr "Ресурсы ввода-вывода "

#: pypowervm/wrappers/logical_partition.py:149
msgid "Memory"
msgstr "Память"

#: pypowervm/wrappers/logical_partition.py:159
msgid "Processors"
msgstr "Процессоры"

#: pypowervm/wrappers/logical_partition.py:176
msgid "LPAR is not in an active state."
msgstr "LPAR не находится в активном состоянии. "

#: pypowervm/wrappers/logical_partition.py:182
msgid "IBM i LPAR does not have restricted I/O."
msgstr "В LPAR IBM i нет ограниченных ресурсов ввода-вывода. "

#: pypowervm/wrappers/logical_partition.py:186
msgid "Source system does not have the IBM i LPAR Mobility Capability."
msgstr "Исходная система не поддерживает мобильные LPAR IBM i. "

#: pypowervm/wrappers/logical_partition.py:191
msgid "IBM i LPAR Live Migration is only supported on POWER7 and higher systems."
msgstr "Оперативная миграция LPAR IBM i поддерживается только в системах POWER7 и выше. "

#: pypowervm/wrappers/logical_partition.py:198
msgid "LPAR is not available for LPM due to missing DLPAR capabilities."
msgstr "LPAR недоступен для LPM, поскольку он не поддерживает DLPAR. "

#: pypowervm/wrappers/logical_partition.py:267
#, python-format
msgid "Invalid IPLSrc '%s'."
msgstr "Недопустимое значение IPLSrc '%s'."

