# Translations template for pypowervm.
# Copyright 2015, 2017 IBM Corp.
# This file is distributed under the same license as the pypowervm project.
# Automatically generated, 2017.
#
msgid ""
msgstr ""
"Project-Id-Version: pypowervm 1.1.3.dev1\n"
"Report-Msgid-Bugs-To: EMAIL@ADDRESS\n"
"POT-Creation-Date: 2017-04-20 10:36-0400\n"
"PO-Revision-Date: 2017-04-20 10:36-0400\n"
"Last-Translator: Automatically generated\n"
"Language-Team: none\n"
"MIME-Version: 1.0\n"
"Content-Type: text/plain; charset=UTF-8\n"
"Content-Transfer-Encoding: 8bit\n"
"Generated-By: Babel 2.4.0\n"

#: pypowervm/adapter.py:131
#, python-format
msgid "Invalid protocol \"%s\""
msgstr "Protocolo no válido \"%s\""

#: pypowervm/adapter.py:137
msgid "Unencrypted communication with PowerVM! Revert configuration to https."
msgstr "Comunicación sin cifrar con PowerVM. Revierta la configuración ahttps."

#: pypowervm/adapter.py:151
msgid "Calculating default audit memento failed, using 'default'."
msgstr "Se ha encontrado un error en el cálculo del memento de auditoría predeterminado, se va a utilizar 'default'."

#: pypowervm/adapter.py:192
msgid "Local authentication not supported on HMC."
msgstr "La autenticación local no está soportada en la HMC."

#: pypowervm/adapter.py:211
#, python-format
msgid "Setting up event listener for %s"
msgstr "Configurando el escucha de sucesos para %s"

#: pypowervm/adapter.py:281
#, python-format
msgid "Unexpected filehandle on %s request"
msgstr "Descriptor de archivo inesperado en la solicitud %s."

#: pypowervm/adapter.py:327
#, python-format
msgid "Unexpected error for %(meth)s %(url)s"
msgstr "Error inesperado para %(meth)s %(url)s."

#: pypowervm/adapter.py:329
#, python-format
msgid "Unexpected error: %(class)s for %(method)s %(url)s: %(excp)s"
msgstr "Error inesperado %(class)s para %(method)s %(url)s: %(excp)s"

#: pypowervm/adapter.py:367
msgid ""
"Re-login has been deemed unsafe. This Session instance should no longer be "
"used."
msgstr ""
"El nuevo inicio de sesión se ha considerado inseguro. Esta instancia de sesión no debería "
"utilizarse."

#: pypowervm/adapter.py:377
#, python-format
msgid "Attempting re-login %s"
msgstr "Intentando volver a iniciar sesión %s"

#: pypowervm/adapter.py:388
#, python-format
msgid ""
"Re-login 401, response body:\n"
"%s"
msgstr ""
"401 de reinicio de sesión, cuerpo de respuesta:\n"
"%s"

#: pypowervm/adapter.py:393
#, python-format
msgid ""
"Re-login failed, resp body:\n"
"%s"
msgstr ""
"Se ha encontrado un error en el reinicio de sesión, cuerpo de respuesta:\n"
"%s"

#: pypowervm/adapter.py:397
#, python-format
msgid ""
"Re-login failed:\n"
"%s"
msgstr ""
"Se ha encontrado un error en el reinicio de sesión:\n"
"%s"

#: pypowervm/adapter.py:416
#, python-format
msgid ""
"Re-attempt failed with another 401, response body:\n"
"%s"
msgstr ""
"Se ha encontrado un error en el reinicio de sesión con otro 401, cuerpo de respuesta:\n"
"%s"

#: pypowervm/adapter.py:419
#, python-format
msgid ""
"suspicious HTTP 401 response for %(method)s %(path)s: token is brand new"
msgstr ""
"respuesta HTTP 401 sospechosa para %(method)s %(path)s: la señal es completamente nueva"

#: pypowervm/adapter.py:461
#, python-format
msgid ""
"Failed to connect to REST server - is the pvm-rest service started?  "
"Retrying %(try_num)d of %(max_tries)d after %(delay)d seconds."
msgstr ""
"No se ha podido establecer la conexión con el servidor REST - ¿se ha iniciado el servicio pvm-rest?  "
"Se están reintentando %(try_num)d de %(max_tries)d después de %(delay)d segundos."

#: pypowervm/adapter.py:468
#, python-format
msgid "Session logging on %s"
msgstr "Iniciando sesión en %s"

#: pypowervm/adapter.py:532
msgid "Failed to parse a session token from the PowerVM response."
msgstr "Se ha encontrado un error en el análisis de una señal de sesión procedente de la respuesta de PowerVM."

#: pypowervm/adapter.py:534 pypowervm/adapter.py:550
#, python-format
msgid " Body= %s"
msgstr " Cuerpo = %s"

#: pypowervm/adapter.py:548
msgid "Failed to parse a session file path from the PowerVM response."
msgstr "Se ha encontrado un error en el análisis de una ruta de archivo de sesión procedente de la respuesta de PowerVM."

#: pypowervm/adapter.py:562
#, python-format
msgid "Token file %s didn't contain a readable session token."
msgstr "El archivo de señal %s no contenía ninguna señal de sesión legible."

#: pypowervm/adapter.py:572
#, python-format
msgid "Session logging off %s"
msgstr "Cerrando sesión de %s"

#: pypowervm/adapter.py:577
msgid "Problem logging off.  Ignoring."
msgstr "Problema al cerrar la sesión. Se ignorará."

#: pypowervm/adapter.py:671
msgid "job must be a JobRequest element"
msgstr "el trabajo debe ser un elemento JobRequest"

#: pypowervm/adapter.py:675
msgid "JobRequest is missing OperationName"
msgstr "a JobRequest le falta OperationName"

#: pypowervm/adapter.py:689 pypowervm/adapter.py:807 pypowervm/adapter.py:846
#: pypowervm/adapter.py:903
#, python-format
msgid "path=%s is not a PowerVM API reference"
msgstr "la ruta=%s no es una referencia de API de PowerVM"

#: pypowervm/adapter.py:918 pypowervm/adapter.py:935
msgid "Invalid file descriptor"
msgstr "Descriptor de archivo no válido"

#: pypowervm/adapter.py:1022 pypowervm/adapter.py:1050
#: pypowervm/adapter.py:1065
msgid "Expected root_id"
msgstr "root_id esperado"

#: pypowervm/adapter.py:1024
msgid "Expected child_type"
msgstr "child_type esperado"

#: pypowervm/adapter.py:1028 pypowervm/adapter.py:1054
#: pypowervm/adapter.py:1059
#, python-format
msgid "Unexpected suffix_type=%s"
msgstr "suffix_type inesperado=%s"

#: pypowervm/adapter.py:1031 pypowervm/adapter.py:1062
msgid "Expected suffix_parm"
msgstr "suffix_parm esperado"

#: pypowervm/adapter.py:1033 pypowervm/adapter.py:1052
#: pypowervm/adapter.py:1067
msgid "Expected child_id"
msgstr "child_id esperado"

#: pypowervm/adapter.py:1036 pypowervm/adapter.py:1045
msgid "Unexpected child_id"
msgstr "child_id inesperado"

#: pypowervm/adapter.py:1038 pypowervm/adapter.py:1047
msgid "Unexpected root_id"
msgstr "root_id inesperado"

#: pypowervm/adapter.py:1069
#, python-format
msgid "Unexpected req_method=%s"
msgstr "req_method inesperado=%s"

#: pypowervm/adapter.py:1138
#, python-format
msgid "Error parsing XML response from PowerVM: %s"
msgstr "Error en el análisis de la respuesta XML procedente de PowerVM: %s"

#: pypowervm/adapter.py:1151
msgid "Response is not an Atom feed/entry"
msgstr "La respuesta no es un feed ni una entrada Atom."

#: pypowervm/adapter.py:1162
msgid "Unexpected HTTP 204 for request"
msgstr "HTTP 204 inesperado para la solicitud"

#: pypowervm/adapter.py:1170
msgid "Unexpectedly empty response body"
msgstr "Cuerpo de respuesta vacío de forma inesperada"

#: pypowervm/adapter.py:1173
#, python-format
msgid ""
"%(err_reason)s:\n"
"request headers: %(reqheaders)s\n"
"\n"
"request body: %(reqbody)s\n"
"\n"
"response headers: %(respheaders)s\n"
"\n"
"response body: %(respbody)s"
msgstr ""
"%(err_reason)s:\n"
"cabeceras de solicitud: %(reqheaders)s\n"
"\n"
"cuerpo de solicitud: %(reqbody)s\n"
"\n"
"cabeceras de respuesta: %(respheaders)s\n"
"\n"
"cuerpo de respuesta: %(respbody)s"

#: pypowervm/adapter.py:1181
#, python-format
msgid "Atom error for %(method)s %(path)s: %(reason)s"
msgstr "Error Atom para %(method)s %(path)s: %(reason)s"

#: pypowervm/adapter.py:1222
msgid "Session must not be None"
msgstr "La sesión no debe ser None (ninguna)."

#: pypowervm/adapter.py:1224
msgid "An event listener is already active on the session."
msgstr "Ya hay un escucha de sucesos activo en la sesión."

#: pypowervm/adapter.py:1243
#, python-format
msgid "Failed to initialize event feed listener: %s"
msgstr "Se ha encontrado un error en la inicialización del escucha de feeds de sucesos: %s"

#: pypowervm/adapter.py:1247
#, python-format
msgid "Application id \"%s\" is not unique"
msgstr "El ID de aplicación \"%s\" no es exclusivo."

#: pypowervm/adapter.py:1256
msgid "Shutting down"
msgstr "Concluyendo"

#: pypowervm/adapter.py:1259
msgid "This handler is already subscribed"
msgstr "Este manejador ya está suscrito."

#: pypowervm/adapter.py:1267
msgid "Handler must be an EventHandler"
msgstr "El manejador debe ser un EventHandler."

#: pypowervm/adapter.py:1270
msgid "This handler not found in subscriber list"
msgstr "Este manejador no se ha encontrado en la lista de suscriptores."

#: pypowervm/adapter.py:1278
#, python-format
msgid "Shutting down EventListener for %s"
msgstr "Cerrando EventListener de %s"

#: pypowervm/adapter.py:1282
#, python-format
msgid "EventListener shutdown complete for %s"
msgstr "Se ha completado el cierre de EventListener para %s"

#: pypowervm/adapter.py:1302
#, python-format
msgid ""
"Error while getting PowerVM events: %s.  (Is the pvm-rest service down?)"
msgstr ""
"Error al obtener sucesos de PowerVM: %s.  (¿El servicio pvm-rest está inactivo?)"

#: pypowervm/adapter.py:1345
#, python-format
msgid "Unexpected EventType=%s"
msgstr "EventType inesperado=%s"

#: pypowervm/adapter.py:1373
msgid "Error while processing PowerVM events"
msgstr "Error al procesar los sucesos de PowerVM."

#: pypowervm/exceptions.py:117
#, python-format
msgid ""
"Unable to derive the appropriate physical FC port for WWPN %(wwpn)s.  The "
"VIOS Extended Attribute Groups may have been insufficient.  The VIOS URI for "
"the query was %(vio_uri)s."
msgstr ""
"No se puede derivar el puerto de canal de fibra físico apropiado para WWPN %(wwpn)s.  Es posible que los "
"grupos de atributos ampliados del VIOS no fueran suficientes.  El identificador universal de recursos del VIOS de la "
"consulta era %(vio_uri)s."

#: pypowervm/exceptions.py:123
#, python-format
msgid "Element not found: %(element_type)s %(element)s"
msgstr "No se ha encontrado el elemento: %(element_type)s %(element)s"

#: pypowervm/exceptions.py:127
#, python-format
msgid "LPAR not found: %(lpar_name)s"
msgstr "No se ha encontrado la LPAR: %(lpar_name)s"

#: pypowervm/exceptions.py:131
#, python-format
msgid "The '%(operation_name)s' operation failed. %(error)s"
msgstr "La operación '%(operation_name)s' ha fallado. %(error)s"

#: pypowervm/exceptions.py:135
#, python-format
msgid ""
"The '%(operation_name)s' operation failed. Failed to complete the task in "
"%(seconds)d seconds."
msgstr ""
"La operación '%(operation_name)s' ha fallado. No se ha podido completar la tarea en "
"%(seconds)d segundos."

#: pypowervm/exceptions.py:140
#, python-format
msgid ""
"Can not perform OS shutdown on Virtual Machine %(lpar_nm)s because its RMC "
"connection is not active."
msgstr ""
"No se puede ejecutar la conclusión del sistema operativo en la máquina virtual %(lpar_nm)s porque su conexión RMC "
"no está activa."

#: pypowervm/exceptions.py:145
#, python-format
msgid "Failed to power off Virtual Machine %(lpar_nm)s: %(reason)s"
msgstr "No se ha podido apagar la máquina virtual %(lpar_nm)s: %(reason)s"

#: pypowervm/exceptions.py:149
#, python-format
msgid ""
"Power off of Virtual Machine %(lpar_nm)s timed out after %(timeout)d seconds."
msgstr ""
"El apagado de la máquina virtual %(lpar_nm)s ha agotado el tiempo de espera después de %(timeout)d segundos."

#: pypowervm/exceptions.py:154
#, python-format
msgid "Failed to power on Virtual Machine %(lpar_nm)s: %(reason)s"
msgstr "No se ha podido encender la máquina virtual %(lpar_nm)s: %(reason)s"

#: pypowervm/exceptions.py:158
#, python-format
msgid ""
"Power on of Virtual Machine %(lpar_nm)s timed out after %(timeout)d seconds."
msgstr ""
"El encendido de la máquina virtual %(lpar_nm)s ha agotado el tiempo de espera después de %(timeout)d segundos."

#: pypowervm/exceptions.py:163
#, python-format
msgid ""
"Unable to remove VLAN %(vlan_id)d as it is the Primary VLAN Identifier on a "
"different Network Bridge."
msgstr ""
"No se puede eliminar la VLAN %(vlan_id)d, ya que es el identificador de VLAN primaria en un "
"puente de red distinto."

#: pypowervm/exceptions.py:168
#, python-format
msgid ""
"Unable to provision VLAN %(vlan_id)d.  It appears to be contained on device "
"'%(dev_name)s' on Virtual I/O Server %(vios)s.  That device is not connected "
"to any Network Bridge (Shared Ethernet Adapter).  Please manually remove the "
"device or add it to the Network Bridge before continuing."
msgstr ""
"No se puede suministrar la VLAN %(vlan_id)d.  Parece que está incluida en el dispositivo "
"'%(dev_name)s' en el servidor de E/S virtual %(vios)s.  Dicho dispositivo no está conectado "
"con ningún puente de red (adaptador Ethernet compartido).  Elimine el dispositivo "
"o añádalo al puente de red antes de continuar."

#: pypowervm/exceptions.py:177
#, python-format
msgid ""
"A Logical Unit with name %(lu_name)s already exists on Shared Storage Pool "
"%(ssp_name)s."
msgstr ""
"Una unidad lógica denominada %(lu_name)s ya exite en la agrupación de almacenamiento compartido "
"%(ssp_name)s."

#: pypowervm/exceptions.py:182
msgid ""
"Unable to find a physical port to map a virtual Fibre Channel port to.  This "
"is due to either a Virtual I/O Server being unavailable, or improper port "
"specification for the physical Fibre Channel ports."
msgstr ""
"No se puede encontrar un puerto físico con el que correlacionar un puerto de canal de fibra virtual.  Esto "
"se debe a que el servidor de E/S virtual no está disponible o a una especificación de puerto "
"incorrecta para los puertos de canal de fibra físicos."

#: pypowervm/exceptions.py:189
msgid ""
"Unable to start the console to the Virtual Machine.  The pypowervm API is "
"running in a non-local mode.  The console can only be deployed when "
"pypowervm is co-located with the PowerVM API."
msgstr ""
"No se puede iniciar la consola en la máquina virtual. La API pypowervm se "
"ejecuta en una modalidad no local. La consola sólo se puede desplegar cuando "
"pypowervm está ubicado conjuntamente con la API PowerVM."

#: pypowervm/exceptions.py:196
#, python-format
msgid "WrapperTask %(name)s has no subtasks!"
msgstr "WrapperTask %(name)s no tiene ninguna subtarea."

#: pypowervm/exceptions.py:200
msgid "FeedTask can't have an empty feed."
msgstr "FeedTask no puede tener un canal de información vacío."

#: pypowervm/exceptions.py:204
#, python-format
msgid "OS denied access to file %(access_file)s."
msgstr "El sistema operativo ha denegado el acceso al archivo %(access_file)s."

#: pypowervm/exceptions.py:208
#, python-format
msgid ""
"OS encountered an I/O error attempting to read file %(access_file)s: "
"%(error)s"
msgstr ""
"El sistema operativo ha encontrado un error de E/S al intentar leer el archivo %(access_file)s: "
"%(error)s"

#: pypowervm/exceptions.py:213
#, python-format
msgid "The migration task failed. %(error)s"
msgstr "La tarea de migración ha fallado. %(error)s"

#: pypowervm/exceptions.py:217
#, python-format
msgid "No load source found for VM %(vm_name)s"
msgstr "No se ha encontrado ningún origen de carga para la máquina virtual %(vm_name)s"

#: pypowervm/exceptions.py:221
#, python-format
msgid ""
"Unable to derive the pg83 encoding for hdisk %(dev_name)s.  The parent_entry "
"attribute is not set.  This may be due to using a PV obtained through an "
"unsupported property chain.  The PV must be accessed via VIOS.phys_vols, VG."
"phys_vols, or VIOS.scsi_mappings[n].backing_storage."
msgstr ""
"No se puede derivar la codificación pg83 para el hdisk %(dev_name)s.  El atributo parent_entry "
"no está establecido.  Puede deberse a la utilización de un volumen físico obtenido mediante una "
"cadena de propiedades no soportada.  Debe accederse al volumen físico mediante VIOS.phys_vols, VG."
"phys_vols o VIOS.scsi_mappings[n].backing_storage."

#: pypowervm/exceptions.py:229
#, python-format
msgid ""
"Found device %(devname)s %(count)d times; expected to find it at most once."
msgstr ""
"Se ha encontrado el dispositivo %(devname)s %(count)d veces; se esperaba encontrarlo una vez como máximo."

#: pypowervm/exceptions.py:244
#, python-format
msgid ""
"FeedTask %(ft_name)s experienced multiple exceptions:\n"
"\t%(concat_msgs)s"
msgstr ""
"FeedTask %(ft_name)s ha experimentado varias excepciones:\n"
"\t%(concat_msgs)s"

#: pypowervm/exceptions.py:254
#, python-format
msgid "Expected to find exactly one management partition; found %(count)d."
msgstr "Se esperaba encontrar una única partición de gestión; se han encontrado %(count)d."

#: pypowervm/exceptions.py:260
#, python-format
msgid ""
"Expected to find exactly one partition with ID %(lpar_id)d; found %(count)d."
msgstr ""
"Se esperaba encontrar exactamente una partición con ID %(lpar_id)d; se ha encontrado %(count)d."

#: pypowervm/exceptions.py:266
#, python-format
msgid "Couldn't find the default Tier on Shared Storage Pool %(ssp_name)s."
msgstr "No se ha podido encontrar el nivel predeterminado en la agrupación de almacenamiento compartido %(ssp_name)s."

#: pypowervm/exceptions.py:275
#, python-format
msgid ""
"The device with UDID %(udid)s was not found on any of the Virtual I/O "
"Servers."
msgstr ""
"El dispositivo con UDID %(udid)s no se ha encontrado en ningún servidor de E/S "
"virtual."

#: pypowervm/exceptions.py:280
#, python-format
msgid ""
"There are not enough Virtual I/O Servers to support the virtual machine's "
"device with UDID %(udid)s."
msgstr ""
"No hay suficientes servidores de E/S virtuales para dar soporte al dispositivo de la máquina "
"virtual con UDID %(udid)s."

#: pypowervm/exceptions.py:285
#, python-format
msgid ""
"The expected fabrics (%(fabrics)s) were not found on any of the Virtual I/O "
"Servers."
msgstr ""
"Los entramados esperados (%(fabrics)s) no se han encontrado en ninguno de los servidores de entrada/salida "
"virtuales."

#: pypowervm/exceptions.py:290
#, python-format
msgid ""
"Can not rebuild the virtual machine.  It is using an I/O type of %(io_type)s "
"which is not supported for VM rebuild."
msgstr ""
"No se puede recrear la máquina virtual.  Está utilizando un tipo de entrada/salida de %(io_type)s "
"que no se admite para la recreación de la máquina virtual."

#: pypowervm/exceptions.py:295
#, python-format
msgid ""
"The number of VFC slots on the target system (%(rebuild_slots)d) does not "
"match the number of slots on the client system (%(original_slots)d).  Unable "
"to rebuild this virtual machine on this system."
msgstr ""
"El número de ranuras de VFC en el sistema de destino (%(rebuild_slots)d) no coincide "
"con el número de ranuras en el sistema cliente (%(original_slots)d).  No se puede "
"recrear esta máquina virtual en este sistema."

#: pypowervm/exceptions.py:302
#, python-format
msgid ""
"To register the slot information of the network device a CNA or VNIC adapter "
"is needed. Instead the following was given: %(wrapper)s."
msgstr ""
"Para registrar la información de la ranura en el dispositivo de red se necesita un adaptador CNA o VNIC. En su lugar, se ha indicado lo siguiente: %(wrapper)s."

#: pypowervm/exceptions.py:308
#, python-format
msgid ""
"There are not enough active Virtual I/O Servers available. Expected %(exp)d; "
"found %(act)d."
msgstr ""
"No hay suficientes servidores de E/S virtuales activos disponibles. Se esperaban %(exp)d; "
"se han encontrado %(act)d."

#: pypowervm/exceptions.py:313
#, python-format
msgid ""
"No Virtual I/O Servers are available.  Attempted to wait for a VIOS to "
"become active for %(wait_time)d seconds.  Please check the RMC connectivity "
"between the PowerVM NovaLink and the Virtual I/O Servers."
msgstr ""
"No hay servidores de E/S virtuales disponibles.  Se ha intentado esperar a que un VIOS pasara "
"a estar activo durante %(wait_time)d segundos.  Compruebe la conectividad RMC "
"entre PowerVM NovaLink y los servidores de E/S virtuales."

#: pypowervm/exceptions.py:323
#, python-format
msgid ""
"Could not find any SR-IOV adapters in Sriov mode and Running state.\n"
"Location | Mode | State\n"
"%(sriov_loc_mode_state)s"
msgstr ""
"No se pueden encontrar adaptadores SR-IOV en modalidad Sriov y estado En ejecución.\n"
"Ubicación | Modalidad | Estado\n"
"%(sriov_loc_mode_state)s"

#: pypowervm/exceptions.py:328
#, python-format
msgid ""
"Unable to fulfill redundancy requirement of %(red)d.  Found %(found_vfs)d "
"viable backing device(s)."
msgstr ""
"No se puede cumplir el requisito de redundancia de %(red)d.  Se ha(n) encontrado %(found_vfs)d "
"dispositivo(s) de respaldo viable(s)."

#: pypowervm/exceptions.py:333
msgid "The Managed System is not vNIC capable."
msgstr "El sistema gestionado no admite vNIC."

#: pypowervm/exceptions.py:337
msgid "There are no active vNIC-capable VIOSes."
msgstr "No hay servidores de E/S virtuales activos que admitan vNIC."

#: pypowervm/exceptions.py:341
#, python-format
msgid ""
"A redundancy of %(red)d was specified, but the Managed System is not vNIC "
"failover capable."
msgstr ""
"Se ha especificado una redundancia de %(red)d, pero el sistema gestionado no admite "
"la migración tras error de vNIC."

#: pypowervm/exceptions.py:346
#, python-format
msgid ""
"A redundancy of %(red)d was specified, but there are no active vNIC failover-"
"capable VIOSes."
msgstr ""
"Se ha especificado una redundancia de %(red)d, pero no hay VIOS activos"
"que admitan la migración tras error de vNIC."

#: pypowervm/exceptions.py:351
#, python-format
msgid ""
"Unable to locate the volume group %(vol_grp)s to store the virtual optical "
"media within.  Unable to create the media repository."
msgstr ""
"No se puede ubicar el grupo de volúmenes %(vol_grp)s en el que almacenar el soporte "
"óptico virtual.  No se puede crear el repositorio de soportes."

#: pypowervm/exceptions.py:357
#, python-format
msgid ""
"The ManagedSystem update was not attempted because changes were requested to "
"one or more SR-IOV physical ports which are in use by vNICs.\n"
"%(warnings)s"
msgstr ""
"La actualización de ManagedSystem no se ha intentado porque se han solicitado cambios a "
"uno o varios puertos físicos SR-IOV que están siendo utilizados por vNIC.\n"
"%(warnings)s"

#: pypowervm/exceptions.py:363
#, python-format
msgid "Unable to create VNC based virtual terminal: %(err)s"
msgstr "No se puede crear la terminal virtual basada en un sistema de red virtual: %(err)s"

#: pypowervm/exceptions.py:367
msgid "The Adapter cache is not supported."
msgstr "La caché del adaptador no es compatible."

#: pypowervm/exceptions.py:371
#, python-format
msgid ""
"Invalid value '%(value)s' for '%(enum)s'.  Valid values are: %(valid_values)s"
msgstr ""
"Valor no válido '%(value)s' para '%(enum)s'.  Los valores válidos son: %(valid_values)s"

#: pypowervm/exceptions.py:376
#, python-format
msgid "No VIOS found with name %(vios_name)s."
msgstr "No se ha encontrado ningún VIOS con el nombre %(vios_name)s."

#: pypowervm/exceptions.py:380
#, python-format
msgid "No volume group found with name %(vg_name)s."
msgstr "No se ha encontrado ningún grupo de volúmenes con el nombre %(vg_name)s."

#: pypowervm/util.py:125
#, python-format
msgid ""
"Proposed extended attribute group '%(arg_xag)s' doesn't match existing "
"extended attribute group '%(path_xag)s'"
msgstr ""
"El grupo de atributos ampliados propuesto '%(arg_xag)s' no coincide con el grupo de "
"atributos ampliados existente '%(path_xag)s'"

#: pypowervm/util.py:221
msgid "Certificate has expired."
msgstr "El certificado ha caducado."

#: pypowervm/util.py:371
#, python-format
msgid "Prefix and suffix together may not be more than %d characters."
msgstr "El prefijo y sufijo juntos no pueden tener más de %d caracteres."

#: pypowervm/util.py:376
msgid "Total length must be at least 1 character."
msgstr "La longitud total debe ser al menos de 1 carácter."

#: pypowervm/util.py:399
msgid "The name parameter must be at least one character long."
msgstr "El parámetro de nombre debe tener al menos un carácter de longitud."

#: pypowervm/util.py:402
#, python-format
msgid ""
"The name parameter must not exceed %d characters when trunk_ok is False."
msgstr ""
"El parámetro de nombre no debe sobrepasar de %d caracteres cuando trunk_ok es False."

#: pypowervm/util.py:500
msgid "Developer error: partial parent specification."
msgstr "Error de desarrollador: especificación de padre parcial."

#: pypowervm/util.py:505
msgid ""
"Developer error: parent_type must be either a string schema type or a "
"Wrapper subclass."
msgstr ""
"Error de desarrollador: parent_type puede ser un tipo de esquema de serie o una "
"subclase de derivador."

#: pypowervm/util.py:602
#, python-format
msgid "Invalid value '%(bad_val)s'.  Expected one of %(good_vals)s, or a list."
msgstr ""
"Valor no válido '%(bad_val)s'.  Se esperaba uno de %(good_vals)s o una lista."

#: pypowervm/helpers/log_helper.py:83
#, python-format
msgid "REQUEST: %s"
msgstr "SOLICITUD: %s"

#: pypowervm/helpers/log_helper.py:103
#, python-format
msgid "RESPONSE: %s"
msgstr "RESPUESTA: %s"

#: pypowervm/tasks/cluster_ssp.py:108
#, python-format
msgid "Waiting for in-progress upload(s) to complete.  Marker LU(s): %s"
msgstr "Esperando a que se completen las subidas en curso. LU de marcador: %s"

#: pypowervm/tasks/cluster_ssp.py:137
msgid "Abdicating in favor of in-progress upload."
msgstr "Renunciando en favor de la cargar en curso."

#: pypowervm/tasks/cluster_ssp.py:147
#, python-format
msgid "Abdicating upload in favor of marker %s."
msgstr "Renunciando a la carga en favor del marcador %s."

#: pypowervm/tasks/cluster_ssp.py:202
#, python-format
msgid "Using already-uploaded image LU %s."
msgstr "Utilizando LU de imagen ya cargada %s."

#: pypowervm/tasks/cluster_ssp.py:212
#, python-format
msgid "Creating marker LU %s"
msgstr "Creando LU de marcador %s"

#: pypowervm/tasks/cluster_ssp.py:228
#, python-format
msgid "Uploading to image LU %(lu)s (marker %(mkr)s)."
msgstr "Cargando en LU de imagen %(lu)s (marcador %(mkr)s)."

#: pypowervm/tasks/cluster_ssp.py:240
#, python-format
msgid "Removing failed LU %s."
msgstr "Eliminando LU con fallos %s."

#: pypowervm/tasks/cna.py:120
#, python-format
msgid "Unable to find the Virtual Switch %s on the system."
msgstr "No se puede encontrar el conmutador virtual %s en el sistema."

#: pypowervm/tasks/cna.py:147
#, python-format
msgid "Unable to find a valid VLAN for Virtual Switch %s."
msgstr "No se ha podido encontrar una VLAN válida para el conmutador virtual %s."

#: pypowervm/tasks/memory.py:102
#, python-format
msgid ""
"Error obtaining host memory overhead for host with UUID '%(host)s': "
"%(error)s."
msgstr ""
"Error al obtener la sobrecarga de memoria de host para el host con el UUID '%(host)s': "
"%(error)s."

#: pypowervm/tasks/partition.py:312
#, python-format
msgid ""
"Timed out waiting for the RMC state of all the powered on Virtual I/O "
"Servers to be active. Wait time was: %(time)d seconds. VIOSes that did not "
"go active were: %(vioses)s."
msgstr ""
"Se ha agotado el tiempo de espera esperando a que el estado de RMC de todos los servidores de E/S virtuales "
"encendidos pasara a ser activo. El tiempo de espera era: %(time)d segundos. Los VIOS que no han pasado "
"a estar activos son: %(vioses)s."

#: pypowervm/tasks/partition.py:354
#, python-format
msgid "Assuming description-less slot is physical I/O: %s"
msgstr "Se considera que la ranura sin descripción es una entrada/salida física: %s"

#: pypowervm/tasks/power.py:88
#, python-format
msgid "Partition %s already powered on."
msgstr "La partición %s ya está encendida."

#: pypowervm/tasks/power.py:136
#, python-format
msgid "Partition %s already powered off."
msgstr "La partición %s ya está apagada."

#: pypowervm/tasks/power.py:199
#, python-format
msgid ""
"Specifying add_parms as a dict is deprecated. Please specify a %s instance "
"instead."
msgstr ""
"La especificación de add_parms como dict ya no se utiliza. Especifique una instancia %s "
"en su lugar."

#: pypowervm/tasks/power.py:265
#, python-format
msgid ""
"IBMi OS normal shutdown failed.  Trying OS immediate shutdown.  Partition: %s"
msgstr ""
"La conclusión normal del sistema operativo de IBMi ha fallado.  Se está intentando efectuar una conclusión inmediata del sistema operativo.  Partición: %s"

#: pypowervm/tasks/power.py:275
#, python-format
msgid ""
"IBMi OS immediate shutdown failed.  Trying VSP normal shutdown.  Partition: "
"%s"
msgstr ""
"La conclusión inmediata del sistema operativo de IBMi ha fallado.  Se está intentando efectuar una conclusión normal del procesador de servicio virtual.  Partición: "
"%s"

#: pypowervm/tasks/power.py:284
#, python-format
msgid ""
"IBMi VSP normal shutdown failed.  Trying VSP hard shutdown.  Partition: %s"
msgstr ""
"La conclusión normal del procesador de servicio virtual de IBMi ha fallado.  Se está intentando efectuar una conclusión forzada del procesador de servicio virtual.  Partición: %s"

#: pypowervm/tasks/power.py:326
#, python-format
msgid ""
"Non-IBMi OS immediate shutdown timed out.  Trying VSP hard shutdown.  "
"Partition: %s"
msgstr ""
"La conclusión inmediata del sistema operativo que no es de IBMi ha agotado el tiempo de espera.  Se está intentando efectuar una conclusión forzada del procesador de servicio virtual.  "
"Partición: %s"

#: pypowervm/tasks/power.py:330
#, python-format
msgid ""
"Non-IBMi OS immediate shutdown failed.  Trying VSP normal shutdown.  "
"Partition: %s"
msgstr ""
"La conclusión inmediata del sistema operativo que no es de IBMi ha fallado.  Se está intentando efectuar una conclusión normal del procesador de servicio virtual.  "
"Partición: %s"

#: pypowervm/tasks/power.py:343
#, python-format
msgid ""
"Non-IBMi VSP normal shutdown failed.  Trying VSP hard shutdown.  Partition: "
"%s"
msgstr ""
"La conclusión normal del procesador de servicio virtual que no es de IBMi ha fallado.  Se está intentando efectuar una conclusión forzada del procesador de servicio virtual.  Partición: "
"%s"

#: pypowervm/tasks/power.py:437
#, python-format
msgid "VSP hard shutdown with default timeout.  Partition: %s"
msgstr "Conclusión forzada del procesador de servicio virtual con tiempo de espera predeterminado.  Partición: %s"

#: pypowervm/tasks/scsi_mapper.py:38
msgid "Retrying modification of SCSI Mapping."
msgstr "Se está reintentando la modificación de la correlación SCSI."

#: pypowervm/tasks/scsi_mapper.py:98
#, python-format
msgid ""
"Found existing mapping of %(stg_type)s storage element %(stg_name)s from "
"Virtual I/O Server %(vios_name)s to client LPAR %(lpar_uuid)s."
msgstr ""
"Se ha encontrado la correlación existente del elemento de almacenamiento de %(stg_type)s %(stg_name)s del "
"servidor de E/S virtual %(vios_name)s a la LPAR de cliente %(lpar_uuid)s."

#: pypowervm/tasks/scsi_mapper.py:117
#, python-format
msgid ""
"Creating mapping of %(stg_type)s storage element %(stg_name)s from Virtual I/"
"O Server %(vios_name)s to client LPAR %(lpar_uuid)s."
msgstr ""
"Se está creando una correlación del elemento de almacenamiento %(stg_type)s %(stg_name)s desde el servidor de E/"
"S virtual %(vios_name)s con la partición lógica de cliente %(lpar_uuid)s."

#: pypowervm/tasks/scsi_mapper.py:433
msgid "Must not specify both match_func and stg_elem."
msgstr "No se debe especificar match_func y stg_elem simultáneamente."

#: pypowervm/tasks/slot_map.py:194
msgid ""
"The register_cna method is deprecated! Please use the register_vnet method."
msgstr ""
"El método register_cna method ya no se utiliza. Utilice el método register_vnet."

#: pypowervm/tasks/slot_map.py:204
msgid "The drop_cna method is deprecated! Please use the drop_vnet method."
msgstr "El método drop_cna ya no se utiliza. Utilice el método drop_vnet."

#: pypowervm/tasks/sriov.py:379
#, python-format
msgid ""
"SR-IOV Physical Port at location %(loc_code)s is backing a vNIC belonging to "
"LPAR %(lpar_name)s (LPAR UUID: %(lpar_uuid)s; vNIC UUID: %(vnic_uuid)s)."
msgstr ""
"El puerto físico SR-IOV en la ubicación %(loc_code)s respalda a un vNIC que pertenece a la "
"partición lógica %(lpar_name)s (UUID de LPAR: %(lpar_uuid)s; UUID de vNIC: %(vnic_uuid)s)."

#: pypowervm/tasks/sriov.py:496
msgid ""
"Making changes to the following SR-IOV physical port labels even though they "
"are in use by vNICs:"
msgstr ""
"Se están realizando cambios en las siguientes etiquetas de puerto físico SR-IOV aunque "
"algunos vNIC las están utilizando:"

#: pypowervm/tasks/storage.py:96
#, python-format
msgid "Failed to delete vio_file with UUID %s.  It must be manually deleted."
msgstr "No se ha podido suprimir vio_file con UUID %s.  Es necesario suprimirlo a mano."

#: pypowervm/tasks/storage.py:348
msgid "Encountered an issue while uploading. Will retry."
msgstr "Se ha encontrado un error al cargar. Se volverá a intentar."

#: pypowervm/tasks/storage.py:522
msgid ""
"The crt_lu_linked_clone method is deprecated!  Please use the crt_lu method "
"(clone=src_lu, size=lu_size_gb)."
msgstr ""
"El método crt_lu_linked_clone ya no se utiliza.  Utilice el método crt_lu "
"(clone=src_lu, size=lu_size_gb)."

#: pypowervm/tasks/storage.py:573
#, python-format
msgid ""
"Disk Logical Unit %(luname)s has no backing image LU.  (UDID: %(udid)s) "
msgstr ""
"La unidad lógica de disco %(luname)s no tiene LU de imagen de refuerzo.  (UDID: %(udid)s) "

#: pypowervm/tasks/storage.py:654
msgid "Unable to locate new vDisk on file upload."
msgstr "No se puede localizar el nuevo vDisk durante la carga de archivo."

#: pypowervm/tasks/storage.py:703
#, python-format
msgid ""
"Ignoring device because it lacks a UDID:\n"
"%s"
msgstr ""
"El dispositivo se ignorará porque carece de UDID:\n"
"%s"

#: pypowervm/tasks/storage.py:709
#, python-format
msgid "Device %s not found in list."
msgstr "El dispositivo %s no se ha encontrado en la lista."

#: pypowervm/tasks/storage.py:738
#, python-format
msgid "Deleting virtual disk %(vdisk)s from volume group %(vg)s"
msgstr "Se está suprimiendo el disco virtual %(vdisk)s del grupo de volúmenes %(vg)s"

#: pypowervm/tasks/storage.py:761
#, python-format
msgid "Deleting virtual optical device %(vopt)s from volume group %(vg)s"
msgstr "Se está suprimiendo el dispositivo óptico virtual %(vopt)s del grupo de volúmenes %(vg)s"

#: pypowervm/tasks/storage.py:817
#, python-format
msgid "Removing LU %(lu_name)s (UDID %(lu_udid)s)"
msgstr "Eliminando LU %(lu_name)s (UDID %(lu_udid)s)"

#: pypowervm/tasks/storage.py:821
#, python-format
msgid ""
"LU %(lu_name)s was not found - it may have been deleted out of band.  (UDID: "
"%(lu_udid)s)"
msgstr ""
"La LU %(lu_name)s no se ha encontrado: podrían haber suprimido fuera de banda.  (UDID: "
"%(lu_udid)s)"

#: pypowervm/tasks/storage.py:839
#, python-format
msgid ""
"Removing Image LU %(lu_name)s because it is no longer in use.  (UDID: "
"%(lu_udid)s)"
msgstr ""
"Eliminando la LU de imagen %(lu_name)s porque ya no está en uso.  (UDID: "
"%(lu_udid)s)"

#: pypowervm/tasks/storage.py:844
#, python-format
msgid "Backing LU %(lu_name)s was not found.  (UDID: %(lu_udid)s)"
msgstr "No se ha encontrado la unidad lógica %(lu_name)s de respaldo.  (UDID: %(lu_udid)s)"

#: pypowervm/tasks/storage.py:870
msgid "Developer error: Either tier or lufeed is required."
msgstr "Error de desarrollador: es necesario tier o lufeed."

#: pypowervm/tasks/storage.py:875
msgid ""
"Developer error: The lufeed parameter must comprise LUEnt EntryWrappers."
msgstr ""
"Error de desarrollador: el parámetro lufeed debe incluir LUEnt EntryWrappers."

#: pypowervm/tasks/storage.py:882
#, python-format
msgid "Deleting LU %(lu_name)s (UDID: %(lu_udid)s)"
msgstr "Suprimiendo LU %(lu_name)s (UDID: %(lu_udid)s)"

#: pypowervm/tasks/storage.py:887
#, python-format
msgid ""
"Ignoring HttpError for LU %(lu_name)s may have been deleted out of band.  "
"(UDID: %(lu_udid)s)"
msgstr ""
"Se ignora HttpError para la unidad lógica %(lu_name)s, podría haberse suprimido fuera de banda.  "
"(UDID: %(lu_udid)s)"

#: pypowervm/tasks/storage.py:940
#, python-format
msgid ""
"Removing %(num_maps)d orphan %(stg_type)s mappings from VIOS %(vios_name)s."
msgstr ""
"Se están eliminando %(num_maps)d correlaciones %(stg_type)s huérfanas del servidor de E/S virtual %(vios_name)s."

#: pypowervm/tasks/storage.py:966
#, python-format
msgid "Removing %(num_maps)d port-less VFC mappings from VIOS %(vios_name)s."
msgstr "Eliminando %(num_maps)d correlaciones de VFC sin puerto del servidor de E/S virtual %(vios_name)s."

#: pypowervm/tasks/storage.py:993
#, python-format
msgid ""
"Removing %(num_maps)d %(stg_type)s mappings associated with LPAR ID "
"%(lpar_id)d from VIOS %(vios_name)s."
msgstr ""
"Se están eliminando %(num_maps)d %(stg_type)s correlaciones asociadas con el ID de LPAR "
"%(lpar_id)d del VIOS %(vios_name)s."

#: pypowervm/tasks/storage.py:1060
#, python-format
msgid ""
"Not removing storage %(stg_name)s of type %(stg_type)s because it cannot be "
"determined whether it is still in use.  Manual verification and cleanup may "
"be necessary."
msgstr ""
"No se va a eliminar el almacenamiento %(stg_name)s del tipo %(stg_type)s porque no se puede "
"determinar si sigue en uso.  Es posible que se requiera una limpieza "
"y una verificación manual."

#: pypowervm/tasks/storage.py:1071
#, python-format
msgid ""
"Storage scrub ignoring storage element %(stg_name)s because it is of "
"unexpected type %(stg_type)s."
msgstr ""
"La depuración del almacenamiento ignorará el elemento del almacenamiento %(stg_name)s porque es de "
"un tipo inesperado: %(stg_type)s."

#: pypowervm/tasks/storage.py:1089
#, python-format
msgid ""
"Scrubbing the following %(vdcount)d Virtual Disks from VIOS %(vios)s: "
"%(vdlist)s"
msgstr ""
"Se están depurando los siguientes %(vdcount)d discos virtuales del VIOS %(vios)s: "
"%(vdlist)s"

#: pypowervm/tasks/storage.py:1097
#, python-format
msgid ""
"Scrubbing the following %(vocount)d Virtual Opticals from VIOS %(vios)s: "
"%(volist)s"
msgstr ""
"Se están depurando los siguientes %(vocount)d discos ópticos virtuales del VIOS %(vios)s: "
"%(volist)s"

#: pypowervm/tasks/storage.py:1168
#, python-format
msgid ""
"Skipping scrub of %(stg_type)s mappings from VIOS %(vios_name)s for the "
"following LPAR IDs because those LPARs exist: %(lpar_ids)s"
msgstr ""
"Se omite la depuración de las correlaciones %(stg_type)s del VIOS %(vios_name)s para los "
"siguientes ID de LPAR porque dichas LPAR existen: %(lpar_ids)s"

#: pypowervm/tasks/vfc_mapper.py:529
#, python-format
msgid ""
"Unable to find appropriate VIOS.  The payload provided was likely "
"insufficient.  The payload data is:\n"
" %s)"
msgstr ""
"No se encuentra el VIOS adecuado. Es probable que la carga útil proporcionada "
"fuera insuficiente. Los datos de carga útil son:\n"
" %s)"

#: pypowervm/tasks/vfc_mapper.py:558
#, python-format
msgid ""
"The matched VFC port map has no backing port set. Adding %(port)s to mapping "
"for client wwpns: %(wwpns)s"
msgstr ""
"La correlación del puerto VFC coincidente no tiene ningún conjunto de puertos de respaldo. Se va(n) a añadir %(port)s a la correlación "
"para wwpn de cliente: %(wwpns)s"

#: pypowervm/tasks/vopt.py:73
msgid ""
"An error occurred querying the virtual optical media repository.  Attempting "
"to re-establish connection with a virtual optical media repository"
msgstr ""
"Se ha producido un error al consultar el repositorio de soportes ópticos virtuales.  Se está intentando "
"restablecer la conexión con un repositorio de soporte óptico virtual"

#: pypowervm/tasks/vterm.py:85
msgid "Unable to close vterm."
msgstr "No se puede cerrar vterm."

#: pypowervm/tasks/vterm.py:137
#, python-format
msgid "Invalid output on vterm open.  Trying to reset the vterm.  Error was %s"
msgstr ""
"Salida no válida en vterm abierto.  Se está intentando restablecer el vterm.  El error era %s"

#: pypowervm/tasks/vterm.py:345
#, python-format
msgid "VNCSocket Listener Listening on ip=%(ip)s port=%(port)s"
msgstr "La escucha de VNCSocket está escuchando en la ip=%(ip)s puerto=%(port)s"

#: pypowervm/tasks/vterm.py:474
#, python-format
msgid "Error negotiating SSL for VNC Repeater: %s"
msgstr "Error al negociar SSL para repetidor VNC: %s"

#: pypowervm/tasks/hdisk/_fc.py:197
#, python-format
msgid ""
"hdisk discovery failed; will scrub stale storage for LPAR IDs %s and retry."
msgstr ""
"El descubrimiento de hdisk ha fallado; se depurará el almacenamiento obsoleto de los ID de LPAR %s y se volverá a intentar."

#: pypowervm/tasks/hdisk/_fc.py:339
#, python-format
msgid "LUA Recovery Successful. Device Found: %s"
msgstr "Recuperación de LUA realizada correctamente. Dispositivo encontrado: %s"

#: pypowervm/tasks/hdisk/_fc.py:343
#, python-format
msgid "ITL Error encountered: %s"
msgstr "Se ha encontrado el error de ITL: %s"

#: pypowervm/tasks/hdisk/_fc.py:345
#, python-format
msgid "%s Device is currently in use."
msgstr "El dispositivo %s está en uso actualmente."

#: pypowervm/tasks/hdisk/_fc.py:347
#, python-format
msgid "%s Device discovered with unknown UDID."
msgstr "Se ha descubierto un dispositivo %s con UDID desconocido."

#: pypowervm/tasks/hdisk/_fc.py:349
#, python-format
msgid "Failed to Discover the Device : %s"
msgstr "No se ha podido descubrir el dispositivo: %s"

#: pypowervm/tasks/hdisk/_fc.py:419
#, python-format
msgid "CLIRunner Error: %s"
msgstr "Error de CLIRunner: %s"

#: pypowervm/tasks/hdisk/_fc.py:451
msgid ""
"QUERY_INVENTORY LUARecovery Job succeeded, but result contained neither "
"OutputXML nor StdOut."
msgstr ""
"El trabajo QUERY_INVENTORY LUARecovery se ha ejecutado con éxito pero el resultado no contenía ni "
"OutputXML ni StdOut."

#: pypowervm/tasks/hdisk/_fc.py:475
#, python-format
msgid ""
"QUERY_INVENTORY produced invalid chunk of XML (%(chunk)s).  Error: %(err)s"
msgstr ""
"QUERY_INVENTORY ha producido un trozo no válido de XML (%(chunk)s).  Error: %(err)s"

#: pypowervm/tasks/hdisk/_fc.py:483
#, python-format
msgid ""
"Failed to find pg83 descriptor in XML output:\n"
"%s"
msgstr ""
"Se ha encontrado un error en la búsqueda del descriptor pg83 en la salida XML:\n"
"%s"

#: pypowervm/tasks/hdisk/_iscsi.py:73
#, python-format
msgid "Invalid device output: %(dev)s"
msgstr "Salida de dispositivo no válida: %(dev)s"

#: pypowervm/tasks/hdisk/_iscsi.py:78
#, python-format
msgid "Expected IQN: %(IQN)s not found on iscsi target %(host_ip)s"
msgstr "IQN esperado: el %(IQN)s no se ha encontrado en destino iscsi %(host_ip)s"

#: pypowervm/tasks/monitor/util.py:421
msgid ""
"Metric data is not available.  This may be due to the metrics being recently "
"initialized."
msgstr ""
"Los datos de métricas no están disponibles.  Puede deberse a que las métricas recientemente se han "
"inicializado."

#: pypowervm/tests/test_i18n.py:33
msgid "This is a test"
msgstr "Esto es una prueba"

#: pypowervm/tests/test_i18n.py:36
msgid "This is a message for which a translation doesn't exist"
msgstr "Este es un mensaje para el que no existe una traducción"

#: pypowervm/utils/retry.py:203
#, python-format
msgid ""
"Attempt %(retry)d of total %(total)d for URI %(uri)s.  Error was a known "
"retry response code: %(resp_code)s"
msgstr ""
"Intento %(retry)d de un total de %(total)d para el URI %(uri)s. El error es un "
"código de respuesta de reintento conocido: %(resp_code)s"

#: pypowervm/utils/retry.py:210
#, python-format
msgid ""
"Attempt %(retry)d of %(total)d failed.  Will retry. The exception was:\n"
" %(except)s."
msgstr ""
"Ha fallado el intento %(retry)d de %(total)d.  Se volverá a intentar. La excepción era: \n"
" %(except)s."

#: pypowervm/utils/transaction.py:348
msgid "Must supply either EntryWrapper or EntryWrapperGetter."
msgstr "Debe proporcionar EntryWrapper o EntryWrapperGetter."

#: pypowervm/utils/transaction.py:374
msgid "Must supply a valid Subtask."
msgstr "Debe proporcionar una subtarea válida."

#: pypowervm/utils/transaction.py:378
#, python-format
msgid "Duplicate 'provides' name %s."
msgstr "Nombre 'provides' duplicado %s."

#: pypowervm/utils/transaction.py:453
#, python-format
msgid "WrapperTask %s has no Subtasks; no-op execution."
msgstr "WrapperTask %s no tiene ninguna subtarea; no se ejecuta ninguna operación."

#: pypowervm/utils/transaction.py:585
msgid "Must supply either a list of EntryWrappers or a FeedGetter."
msgstr "Debe proporcionar una lista de EntryWrappers o un FeedGetter."

#: pypowervm/utils/transaction.py:764
#, python-format
msgid "FeedTask %s has no Subtasks; no-op execution."
msgstr "FeedTask %s no tiene ninguna subtarea; no se ejecuta ninguna operación."

#: pypowervm/utils/transaction.py:789
#, python-format
msgid ""
"FeedTask %s experienced multiple exceptions. They are logged individually "
"below."
msgstr ""
"FeedTask %s ha experimentado varias excepciones. Aparecen registradas de forma individual "
"a continuación."

#: pypowervm/utils/validation.py:161
#, python-format
msgid ""
"Insufficient available %(res_name)s on host for virtual machine "
"'%(instance_name)s' (%(requested)s requested, %(avail)s available)"
msgstr ""
"%(res_name)s disponibles insuficientes en el host para la máquina virtual "
"'%(instance_name)s' (%(requested)s solicitados, %(avail)s disponibles)"

#: pypowervm/utils/validation.py:189
msgid "memory"
msgstr "memoria"

#: pypowervm/utils/validation.py:210
#, python-format
msgid ""
"The virtual machine must be powered off before changing the minimum or "
"maximum memory. Power off virtual machine %s and try again."
msgstr ""
"La máquina virtual se debe apagar antes de cambiar la memoria mínima o "
"máxima. Apague la máquina virtual %s y vuelva a intentarlo."

#: pypowervm/utils/validation.py:215
#, python-format
msgid ""
"The virtual machine must be powered off before changing the expansion "
"factor. Power off virtual machine %s and try again."
msgstr ""
"La máquina virtual se debe apagar antes de cambiar el factor de "
"expansión. Apague la máquina virtual %s y vuelva a intentarlo."

#: pypowervm/utils/validation.py:302
msgid "CPUs"
msgstr "CPU"

#: pypowervm/utils/validation.py:318
msgid "processing units"
msgstr "unidades de proceso"

#: pypowervm/utils/validation.py:359
#, python-format
msgid ""
"The virtual machine must be powered off before changing the minimum or "
"maximum processors. Power off virtual machine %s and try again."
msgstr ""
"La máquina virtual se debe apagar antes de cambiar la memoria mínima o "
"máximos. Apague la máquina virtual %s y vuelva a intentarlo."

#: pypowervm/utils/validation.py:369
#, python-format
msgid ""
"The virtual machine must be powered off before changing the minimum or "
"maximum processor units. Power off virtual machine %s and try again."
msgstr ""
"La máquina virtual se debe apagar antes de cambiar la memoria mínima o "
"máximas. Apague la máquina virtual %s y vuelva a intentarlo."

#: pypowervm/utils/validation.py:385
#, python-format
msgid ""
"The virtual machine must be powered off before changing the processor "
"compatibility mode. Power off virtual machine %s and try again."
msgstr ""
"La máquina virtual se debe apagar antes de cambiar la modalidad de compatibilidad "
"del procesador. Apague la máquina virtual %s y vuelva a intentarlo."

#: pypowervm/utils/validation.py:393
#, python-format
msgid ""
"The virtual machine must be powered off before changing the processing mode. "
"Power off virtual machine %s and try again."
msgstr ""
"La máquina virtual debe apagarse antes de cambiar la modalidad de proceso. "
"Apague la máquina virtual %s y vuelva a intentarlo."

#: pypowervm/utils/validation.py:422
#, python-format
msgid ""
"The desired processors (%(vcpus)d) cannot be above the maximum allowed "
"processors per partition (%(max_allowed)d) for virtual machine "
"'%(instance_name)s'."
msgstr ""
"El número deseado de procesadores (%(vcpus)d) no puede ser mayor que el número máximo de procesadores "
"permitidos por partición (%(max_allowed)d) para la máquina virtual "
"'%(instance_name)s'."

#: pypowervm/utils/validation.py:434
#, python-format
msgid ""
"The maximum processors (%(vcpus)d) cannot be above the maximum system "
"capacity processor limit (%(max_allowed)d) for virtual machine "
"'%(instance_name)s'."
msgstr ""
"El número máximo de procesadores (%(vcpus)d) no puede ser mayor que el límite máximo "
"de capacidad del procesador (%(max_allowed)d) para la máquina virtual "
"'%(instance_name)s'."

#: pypowervm/utils/validation.py:506
#, python-format
msgid ""
"The virtual machine must be powered off before changing the simplified "
"remote restart capability. Power off virtual machine %s and try again."
msgstr ""
"La máquina virtual se debe apagar antes de cambiar la capacidad de reinicio "
"remoto simplificado. Apague la máquina virtual %s y vuelva a intentarlo."

#: pypowervm/wrappers/base_partition.py:424
msgid "Partition does not have an active RMC connection."
msgstr "La partición no tiene una conexión RMC activa."

#: pypowervm/wrappers/base_partition.py:427
#, python-format
msgid "Partition does not have an active DLPAR capability for %s."
msgstr "La partición no tiene una prestación DLPAR activa para %s."

#: pypowervm/wrappers/base_partition.py:439
msgid "I/O"
msgstr "E/S"

#: pypowervm/wrappers/base_partition.py:449
msgid "Memory"
msgstr "Memoria"

#: pypowervm/wrappers/base_partition.py:459
msgid "Processors"
msgstr "Procesadores"

#: pypowervm/wrappers/base_partition.py:639
#, python-format
msgid "Invalid KeylockPos '%s'."
msgstr "KeylockPos no válido '%s'."

#: pypowervm/wrappers/base_partition.py:650
#, python-format
msgid "Invalid BootMode '%s'."
msgstr "BootMode no válido '%s'."

#: pypowervm/wrappers/base_partition.py:1436
msgid "IOSlot.adapter is deprecated!  Use IOSlot.io_adapter instead."
msgstr "IOSlot.adapter está en desuso. Utilice IOSlot.io_adapter en su lugar."

#: pypowervm/wrappers/enterprise_pool.py:143
#, python-format
msgid ""
"Unable to determine master management console MTMS (machine type, model, "
"serial number) from %(identifier)s because no %(param)s was marked as the "
"master console for the pool."
msgstr ""
"No se ha podido determinar el MTMS (tipo de máquina, modelo, número de serie) "
"de la consola de gestión maestra a partir del %(identifier)s porque no se ha marcado %(param)s como "
"consola maestra para la agrupación."

#: pypowervm/wrappers/entry_wrapper.py:251
msgid "Cannot set uuid."
msgstr "No se puede establecer el UUID."

#: pypowervm/wrappers/entry_wrapper.py:443
#, python-format
msgid "Cannot convert %(property_name)s='%(value)s' in object %(pvmobject)s"
msgstr "No se puede convertir %(property_name)s='%(value)s' en el objeto %(pvmobject)s"

#: pypowervm/wrappers/entry_wrapper.py:586
msgid ""
"Refusing set href over multiple links.\n"
"Path: %{path}s\n"
"Number of links found: %{nlinks}d"
msgstr ""
"Se rechaza establecer href en varios enlaces.\n"
"Vía de acceso: %{path}s\n"
"Número de enlaces encontrados: %{nlinks}d"

#: pypowervm/wrappers/entry_wrapper.py:635
msgid "Refusing to construct and wrap an Element without a tag."
msgstr "Se rechaza construir y derivar un elemento sin un código."

#: pypowervm/wrappers/entry_wrapper.py:760
msgid "Response is missing 'entry' property."
msgstr "Falta la propiedad 'entry' en la respuesta."

#: pypowervm/wrappers/entry_wrapper.py:774
#, python-format
msgid "Must supply a Response or Entry to wrap.  Got %s"
msgstr "Debe proporcionar una respuesta o entrada para ajustar. Se obtuvo %s"

#: pypowervm/wrappers/entry_wrapper.py:861
msgid ""
"Developer error: specify 'parent' or ('parent_type' and 'parent_uuid') to "
"retrieve a CHILD object."
msgstr ""
"Error de desarrollador: especifique 'parent' o ('parent_type' y 'parent_uuid') para "
"recuperar un objeto CHILD."

#: pypowervm/wrappers/entry_wrapper.py:866
msgid "Specify either 'uuid' or 'root_id' when requesting a ROOT object."
msgstr "Especifique 'uuid' o 'root_id' al solicitar un objeto ROOT."

#: pypowervm/wrappers/entry_wrapper.py:879
msgid ""
"Both parent_type and parent_uuid are required when retrieving a CHILD feed "
"or entry."
msgstr ""
"Tanto parent_type como parent_uuid son necesarios al recuperar una entrada o "
"feed HIJO (CHILD)."

#: pypowervm/wrappers/entry_wrapper.py:882
msgid "Specify the parent's UUID via the parent_uuid parameter."
msgstr "Especifique el UUID del padre mediante el parámetro parent_uuid."

#: pypowervm/wrappers/entry_wrapper.py:886
msgid "Specify either 'uuid' or 'child_id' when requesting a CHILD object."
msgstr "Especifique 'uuid' o 'child_id' al solicitar un objeto CHILD."

#: pypowervm/wrappers/entry_wrapper.py:1001
msgid "Parent UUID specified without parent type."
msgstr "Se ha especificado el UUID sin un tipo padre."

#: pypowervm/wrappers/entry_wrapper.py:1004
msgid "The search() method requires exactly one key=value argument."
msgstr "El método search() requiere exactamente un argumento clave=valor."

#: pypowervm/wrappers/entry_wrapper.py:1035
#, python-format
msgid "Wrapper class %(class)s does not support search key '%(key)s'."
msgstr "La clase de derivador %(class)s no da soporte a la clave de búsqueda '%(key)s'."

#: pypowervm/wrappers/entry_wrapper.py:1135
msgid ""
"The 'xag' parameter to EntryWrapper.update is deprecated!  At best, using it "
"will result in a no-op.  At worst, it will give you incurable etag mismatch "
"errors."
msgstr ""
"El parámetro 'xag' para EntryWrapper.update ya no se utiliza.  En el mejor de los casos, su uso "
"dará como resultado que se no realizará ninguna operación.  En el peor de los casos, le dará errores de no coincidencia "
"etag irremediables."

#: pypowervm/wrappers/entry_wrapper.py:1403
msgid "No such child element."
msgstr "No existe ningún elemento hijo de este tipo."

#: pypowervm/wrappers/entry_wrapper.py:1464
msgid "Cannot set UUID on Wrapper with no Metadata."
msgstr "No se puede establecer el UUID en el derivador sin metadatos."

#: pypowervm/wrappers/entry_wrapper.py:1469
#, python-format
msgid "uuid value not valid: %s"
msgstr "El valor del UUID no es válido: %s"

#: pypowervm/wrappers/entry_wrapper.py:1524
msgid "Must specify a Wrapper subclass."
msgstr "Debe especificar una subclase de derivador."

#: pypowervm/wrappers/entry_wrapper.py:1533
msgid "Must specify both parent class and parent UUID, or neither."
msgstr "Debe especificar una clase padre y un UUID padre, o ninguno de los dos."

#: pypowervm/wrappers/job.py:276
#, python-format
msgid "Job %(job_id)s monitoring for %(time)i seconds."
msgstr "El trabajo %(job_id)s supervisará durante %(time)i segundos."

#: pypowervm/wrappers/job.py:327
#, python-format
msgid ""
"Issuing cancel request for job %(job_id)s. Will poll the job indefinitely "
"for termination."
msgstr ""
"Se está emitiendo una solicitud de cancelación para el trabajo %(job_id)s. Sondeará el trabajo de forma indefinida "
"para comprobar si ha terminado."

#: pypowervm/wrappers/job.py:343
#, python-format
msgid "Job %s not deleted. Job is in running state."
msgstr "El trabajo %s no se ha suprimido. El trabajo se encuentra en estado de ejecución."

#: pypowervm/wrappers/logical_partition.py:169
msgid "LPAR is not in an active state."
msgstr "La LPAR no está en un estado activo."

#: pypowervm/wrappers/logical_partition.py:179
msgid "Target system does not have the IBM i LPAR Mobility Capability."
msgstr "El sistema de destino no tiene la prestación IBM i LPAR Mobility."

#: pypowervm/wrappers/logical_partition.py:183
msgid "IBM i LPAR does not have restricted I/O."
msgstr "La LPAR de IBM i no tiene E/S restringida."

#: pypowervm/wrappers/logical_partition.py:187
msgid "Source system does not have the IBM i LPAR Mobility Capability."
msgstr "El sistema de origen no tiene la prestación de movilidad de LPAR de IBM i."

#: pypowervm/wrappers/logical_partition.py:191
msgid "LPAR does not have an active RMC connection."
msgstr "La LPAR no tiene una conexión RMC activa."

#: pypowervm/wrappers/logical_partition.py:194
msgid "LPAR is the management partition"
msgstr "La partición lógica LPAR es la partición de gestión"

#: pypowervm/wrappers/logical_partition.py:198
msgid "LPAR is not available for LPM due to missing DLPAR capabilities."
msgstr "La LPAR no está disponible para LPM debido a que faltan prestaciones DLPAR."

#: pypowervm/wrappers/logical_partition.py:215
#: pypowervm/wrappers/logical_partition.py:224
#: pypowervm/wrappers/logical_partition.py:232
msgid ""
"This is not the property you are looking for.  Use srr_enabled in a NovaLink "
"environment."
msgstr ""
"Esta no es la propiedad que busca.  Utilice srr_enabled en un entorno de "
"NovaLink."

#: pypowervm/wrappers/logical_partition.py:268
#, python-format
msgid "Invalid IPLSrc '%s'."
msgstr "IPLSrc no válido '%s'."

#: pypowervm/wrappers/managed_system.py:428
msgid "This property is deprecated!. Use pci_subsys_dev_id instead."
msgstr "Esta propiedad ya no se utiliza. Utilice en su lugar pci_subsys_dev_id."

#: pypowervm/wrappers/managed_system.py:440
msgid "This property is deprecated!. Use pci_rev_id instead."
msgstr "Esta propiedad ya no se utiliza. Utilice en su lugar pci_rev_id."

#: pypowervm/wrappers/managed_system.py:456
msgid "This property is deprecated!. Use pci_subsys_vendor_id instead."
msgstr "Esta propiedad ya no se utiliza. Utilice en su lugar pci_subsys_vendor_id."

#: pypowervm/wrappers/managed_system.py:468
msgid "This property is deprecated!. Use drc_index instead."
msgstr "Esta propiedad ya no se utiliza. Utilice en su lugar drc_index."

#: pypowervm/wrappers/managed_system.py:480
msgid "This property is deprecated!. Use drc_name instead."
msgstr "Esta propiedad ya no se utiliza. Utilice en su lugar drc_name."

#: pypowervm/wrappers/storage.py:651
#, python-format
msgid ""
"PV had encoded pg83 descriptor \"%(pg83_raw)s\", but it failed to decode "
"(%(type_error)s)."
msgstr ""
"PV había codificado el descriptor pg83 \"%(pg83_raw)s\", pero no lo ha podido decodificar "
"(%(type_error)s)."

#: pypowervm/wrappers/virtual_io_server.py:163
msgid ""
"The 'xags' property of the VIOS EntryWrapper class is deprecated!  Please "
"use values from pypowervm.const.XAG instead."
msgstr ""
"La propiedad 'xags' de la clase VIOS EntryWrapper está obsoleta. "
"En su lugar, use valores de pypowervm.const.XAG."

#: pypowervm/wrappers/virtual_io_server.py:400
msgid "Partition of VIOS type is not LPM capable"
msgstr "La partición del tipo de VIOS no es apta para LPM"

#: pypowervm/wrappers/virtual_io_server.py:655
msgid "Can't specify target device LUA without a backing storage device!"
msgstr "No se puede especificar LUA de dispositivo de destino sin un dispositivo de almacenamiento de respaldo."

# ENGL1SH_VERS10N 13712_53 DO NOT REMOVE OR CHANGE THIS LINE
# T9N_SRC_ID 23
# T9N_SH1P_STR1NG PV133AAP001 2
